2021-03-29 21:06:54,299 [INFO]  ----------START----------
2021-03-29 21:07:37,666 [ERROR]  Command 'None' in image 'sha256:14635c3d842f5b87901d8e667d9bf4a8ffd901a91a1ec5f4db54fd34951e188b' returned non-zero exit status 1: b'Traceback (most recent call last):\n  File "/tiler/gen_tiles.py", line 1, in <module>\n    import cv2 \n  File "/usr/local/lib/python3.9/site-packages/cv2/__init__.py", line 5, in <module>\n    from .cv2 import *\nImportError: libGL.so.1: cannot open shared object file: No such file or directory\n'
2021-03-29 21:07:37,667 [ERROR]  <proc0> tiler: RunFailed
2021-03-29 21:07:52,244 [ERROR]  <proc0> metaflow: BuildFailed
2021-03-29 21:08:11,126 [INFO]  <proc0> tinygrad: Success
2021-03-29 21:08:18,983 [ERROR]  <proc0> sktime: BuildFailed
2021-03-29 21:08:43,380 [INFO]  <proc0> scalene: Success
2021-03-29 21:10:02,625 [INFO]  <proc0> Python-crawler-tutorial-starts-from-zero: Success
2021-03-29 21:10:14,058 [INFO]  <proc0> jd-assistant: Success
2021-03-29 21:10:28,694 [INFO]  <proc0> autoscraper: Success
2021-03-29 21:10:36,220 [INFO]  <proc0> bullet: Success
2021-03-29 21:10:51,352 [INFO]  <proc0> pipx: Success
2021-03-29 21:11:38,894 [ERROR]  <proc0> DeepLearning: BuildFailed
2021-03-29 21:11:50,555 [ERROR]  <proc0> OneForAll: BuildFailed
2021-03-29 21:11:56,460 [ERROR]  Command 'None' in image 'sha256:1730b2d85e66aaa4eefcdf85cb00d5aa0d157e8b44e75d698d907d0068c61444' returned non-zero exit status 1: b'Traceback (most recent call last):\n  File "//learn_math_fast/build_toc.py", line 67, in <module>\n    gen_toc(filename)\n  File "//learn_math_fast/build_toc.py", line 53, in gen_toc\n    md = _read_md(filename)\n  File "//learn_math_fast/build_toc.py", line 48, in _read_md\n    with open(filename, \'r\') as f:\nFileNotFoundError: [Errno 2] No such file or directory: \'README.md\'\n'
2021-03-29 21:11:56,460 [ERROR]  <proc0> learn_math_fast: Success
2021-03-29 21:13:03,894 [INFO]  <proc0> akshare: Success
2021-03-29 21:13:18,733 [ERROR]  Command 'None' in image 'sha256:cb36a169e9da4b301ec7621288d321ecd217d5538a14b48cdbacc5b436a1d791' returned non-zero exit status 1: b'Traceback (most recent call last):\n  File "//Summer2021-Internships/sync.py", line 36, in <module>\n    html = parse_markdown_to_html_table()\n  File "//Summer2021-Internships/sync.py", line 9, in parse_markdown_to_html_table\n    readme = open("README.md", \'r\').read()\nFileNotFoundError: [Errno 2] No such file or directory: \'README.md\'\n'
2021-03-29 21:13:18,734 [ERROR]  <proc0> Summer2021-Internships: Success
2021-03-29 21:14:34,380 [ERROR]  <proc0> koalas: BuildFailed
2021-03-29 21:14:54,010 [ERROR]  Command 'None' in image 'sha256:d459e1b829cd4be14f7754b4bd3ab93b2ad3d533a722ecbf604a9ca0e0e86b7a' returned non-zero exit status 1: b'Traceback (most recent call last):\n  File "/usr/local/bin/kb", line 5, in <module>\n    from kb.main import main\n  File "/usr/local/lib/python3.9/site-packages/kb/main.py", line 21, in <module>\n    from kb.commands.add import add\n  File "/usr/local/lib/python3.9/site-packages/kb/commands/add.py", line 20, in <module>\n    import kb.db as db\n  File "/usr/local/lib/python3.9/site-packages/kb/db.py", line 21, in <module>\n    from kb.entities.artifact import Artifact\n  File "/usr/local/lib/python3.9/site-packages/kb/entities/artifact.py", line 17, in <module>\n    @attr.s(auto_attribs=True, frozen=True, slots=True)\nAttributeError: module \'attr\' has no attribute \'s\'\n'
2021-03-29 21:14:54,011 [ERROR]  <proc0> kb: Success
2021-03-29 21:19:06,411 [ERROR]  <proc0> ResNeSt: BuildFailed
2021-03-29 21:20:26,559 [INFO]  <proc0> ECommerceCrawlers-TouTiao: Success
2021-03-29 21:21:56,967 [INFO]  <proc0> ECommerceCrawlers-East_money: Success
2021-03-29 21:22:00,182 [INFO]  <proc0> RAdam: Success
2021-03-29 21:22:13,556 [INFO]  <proc0> newscatcher: Success
2021-03-29 21:22:37,394 [INFO]  <proc0> GitHub520: Success
2021-03-29 21:26:27,154 [INFO]  <proc0> vit-pytorch: Success
2021-03-29 21:30:35,731 [ERROR]  Command 'None' in image 'sha256:4f39eaceca00e17de1b13f015c5fd7b15466b48a248643e607ef9bca191112fb' returned non-zero exit status 1: b'Traceback (most recent call last):\n  File "/VideoPose3D/run.py", line 41, in <module>\n    dataset = Human36mDataset(dataset_path)\n  File "/VideoPose3D/common/h36m_dataset.py", line 234, in __init__\n    data = np.load(path, allow_pickle=True)[\'positions_3d\'].item()\n  File "/usr/local/lib/python3.9/site-packages/numpy/lib/npyio.py", line 416, in load\n    fid = stack.enter_context(open(os_fspath(file), "rb"))\nFileNotFoundError: [Errno 2] No such file or directory: \'data/data_3d_h36m.npz\'\n'
2021-03-29 21:30:35,731 [ERROR]  <proc0> VideoPose3D: Success
2021-03-29 21:30:46,745 [INFO]  <proc0> real-url: Success
2021-03-29 21:30:55,358 [ERROR]  <proc0> clearml: BuildFailed
2021-03-29 21:35:51,432 [INFO]  <proc0> captum: Success
2021-03-29 21:39:43,971 [ERROR]  Command 'None' in image 'sha256:6bc821d84ecd971010005337cd392167061d6ef5bd25e68e770d18e46284f9b4' returned non-zero exit status 1: b'Traceback (most recent call last):\n  File "/UGATIT-pytorch/main.py", line 1, in <module>\n    from UGATIT import UGATIT\n  File "/UGATIT-pytorch/UGATIT.py", line 6, in <module>\n    from utils import *\n  File "/UGATIT-pytorch/utils.py", line 2, in <module>\n    import os, cv2, torch\n  File "/usr/local/lib/python3.9/site-packages/cv2/__init__.py", line 5, in <module>\n    from .cv2 import *\nImportError: libGL.so.1: cannot open shared object file: No such file or directory\n'
2021-03-29 21:39:43,971 [ERROR]  <proc0> UGATIT-pytorch: RunFailed
2021-03-29 21:39:47,846 [ERROR]  <proc0> arxiv-latex-cleaner: BuildFailed
2021-03-29 21:40:12,722 [INFO]  <proc0> GeneralNewsExtractor: Success
2021-03-29 21:40:27,041 [ERROR]  Command 'None' in image 'sha256:46c6c5d88f57a977890d58ca155903bd524f9d42a80c46c382525a62ebad391c' returned non-zero exit status 1: b'Traceback (most recent call last):\n  File "/DXY-COVID-19-Crawler/main.py", line 12, in <module>\n    crawler.run()\n  File "/DXY-COVID-19-Crawler/service/crawler.py", line 31, in run\n    self.crawler()\n  File "/DXY-COVID-19-Crawler/service/crawler.py", line 46, in crawler\n    soup = BeautifulSoup(r.content, \'lxml\')\n  File "/usr/local/lib/python3.9/site-packages/bs4/__init__.py", line 243, in __init__\n    raise FeatureNotFound(\nbs4.FeatureNotFound: Couldn\'t find a tree builder with the features you requested: lxml. Do you need to install a parser library?\n'
2021-03-29 21:40:27,042 [ERROR]  <proc0> DXY-COVID-19-Crawler: ImportError
2021-03-29 21:40:34,903 [ERROR]  <proc0> facenet-pytorch: BuildFailed
2021-03-29 21:40:44,499 [ERROR]  Command 'None' in image 'sha256:f12047334df5fd4d303844ae3b4af57b99e64e106d6290df8935d039beec0274' returned non-zero exit status 1: b"\n*******************************************************************************\n/PrettyErrors/test.py\n19 <module>\n    exception_file_color=pretty_errors.BRIGHT_BLUE\n)\nirrelevant = pretty_errors.config.copy()\nirrelevant.line_color = irrelevant.code_color = irrelevant.filename_color = irrelevant.function_color = irrelevant.line_number_color = (\n    pretty_errors.GREY\n)\npretty_errors.pathed_config(irrelevant, 'c:/python', 'c:/users')\n\n\nimport os\nos.rename('nofile', 'stillnofile')\n\nFileNotFoundError:\n2\nNo such file or directory\nnofile\nstillnofile\n"
2021-03-29 21:40:44,499 [ERROR]  <proc0> PrettyErrors: Success
2021-03-29 21:41:25,825 [INFO]  <proc0> m2cgen: Success
2021-03-29 21:41:52,650 [INFO]  <proc0> dirmap: Success
2021-03-29 21:41:56,243 [ERROR]  <proc0> latexify_py: BuildFailed
2021-03-29 21:42:22,874 [ERROR]  Command 'None' in image 'sha256:d5ba7ebb7aebe32c63cb60c020fe27562498746e5f23fdda444096282e91da53' returned non-zero exit status 1: b'Traceback (most recent call last):\n  File "/springer_free_books/main.py", line 48, in <module>\n    books = pd.read_excel(table_url)\n  File "/usr/local/lib/python3.9/site-packages/pandas/util/_decorators.py", line 299, in wrapper\n    return func(*args, **kwargs)\n  File "/usr/local/lib/python3.9/site-packages/pandas/io/excel/_base.py", line 336, in read_excel\n    io = ExcelFile(io, storage_options=storage_options, engine=engine)\n  File "/usr/local/lib/python3.9/site-packages/pandas/io/excel/_base.py", line 1114, in __init__\n    self._reader = self._engines[engine](self._io, storage_options=storage_options)\n  File "/usr/local/lib/python3.9/site-packages/pandas/io/excel/_xlrd.py", line 24, in __init__\n    import_optional_dependency("xlrd", extra=err_msg)\n  File "/usr/local/lib/python3.9/site-packages/pandas/compat/_optional.py", line 109, in import_optional_dependency\n    raise ImportError(msg) from None\nImportError: Missing optional dependency \'xlrd\'. Install xlrd >= 1.0.0 for Excel support Use pip or conda to install xlrd.\n'
2021-03-29 21:42:22,875 [ERROR]  <proc0> springer_free_books: RunFailed
2021-03-29 21:42:29,821 [ERROR]  <proc0> stumpy: BuildFailed
2021-03-29 21:45:38,054 [INFO]  <proc0> SegLoss: Success
2021-03-29 21:45:47,728 [INFO]  <proc0> coding-problems: Success
2021-03-29 21:46:01,755 [INFO]  <proc0> dongbei: Success
2021-03-29 21:46:12,262 [INFO]  <proc0> returns: Success
2021-03-29 21:46:25,761 [INFO]  <proc0> xxh: Success
2021-03-29 21:46:44,566 [ERROR]  Command 'None' in image 'sha256:3b5597a889c5e736ddf7af96db83337c44f7dea1c83074c059ca61db078e5ca3' returned non-zero exit status 1: b'Traceback (most recent call last):\n  File "/usr/local/lib/python3.9/site-packages/apistar/cli.py", line 84, in _load_config\n    config = apistar.validate(content, format="config", encoding="yaml")\n  File "/usr/local/lib/python3.9/site-packages/apistar/core.py", line 54, in validate\n    token = tokenize(schema)\n  File "/usr/local/lib/python3.9/site-packages/typesystem/tokenize/tokenize_yaml.py", line 26, in tokenize_yaml\n    assert yaml is not None, "\'pyyaml\' must be installed."\nAssertionError: \'pyyaml\' must be installed.\n\nDuring handling of the above exception, another exception occurred:\n\nTraceback (most recent call last):\n  File "/usr/local/bin/apistar", line 8, in <module>\n    sys.exit(cli())\n  File "/usr/local/lib/python3.9/site-packages/click/core.py", line 764, in __call__\n    return self.main(*args, **kwargs)\n  File "/usr/local/lib/python3.9/site-packages/click/core.py", line 717, in main\n    rv = self.invoke(ctx)\n  File "/usr/local/lib/python3.9/site-packages/click/core.py", line 1137, in invoke\n    return _process_result(sub_ctx.command.invoke(sub_ctx))\n  File "/usr/local/lib/python3.9/site-packages/click/core.py", line 956, in invoke\n    return ctx.invoke(self.callback, **ctx.params)\n  File "/usr/local/lib/python3.9/site-packages/click/core.py", line 555, in invoke\n    return callback(*args, **kwargs)\n  File "/usr/local/lib/python3.9/site-packages/apistar/cli.py", line 127, in validate\n    config = _load_config(options, verbose=verbose)\n  File "/usr/local/lib/python3.9/site-packages/apistar/cli.py", line 85, in _load_config\n    except (ParseError, ValidationError) as exc:\nNameError: name \'ParseError\' is not defined\n'
2021-03-29 21:46:44,566 [ERROR]  <proc0> apistar: Success
2021-03-29 21:47:42,718 [INFO]  <proc0> pandarallel: Success
2021-03-29 21:48:03,775 [ERROR]  Command 'None' in image 'sha256:8fb20ff589e44fbdb2672c34e19b4cc4f55281711cbe22623898b8cc2a34372e' returned non-zero exit status 1: b'Traceback (most recent call last):\n  File "/DecryptLogin/test.py", line 1, in <module>\n    from DecryptLogin import login\n  File "/DecryptLogin/DecryptLogin/login.py", line 11, in <module>\n    from .core import *\n  File "/DecryptLogin/DecryptLogin/core/__init__.py", line 4, in <module>\n    from .migu import migu\n  File "/DecryptLogin/DecryptLogin/core/migu.py", line 11, in <module>\n    import execjs\nModuleNotFoundError: No module named \'execjs\'\n'
2021-03-29 21:48:03,775 [ERROR]  <proc0> DecryptLogin: RunFailed
2021-03-29 21:48:11,935 [ERROR]  <proc0> webpy: BuildFailed
2021-03-29 21:48:48,867 [INFO]  <proc0> SSRFmap: Success
2021-03-29 21:48:56,517 [ERROR]  Command 'None' in image 'sha256:f351548a059cfbd09e3a9bae6d0aea939f9f2a2ccfc59fdeed9b23695173943b' returned non-zero exit status 1: b'Traceback (most recent call last):\n  File "/python-for-absolute-beginners-course/code/07-data-structures/rocks-game/rpsgame.py", line 102, in <module>\n    main()\n  File "/python-for-absolute-beginners-course/code/07-data-structures/rocks-game/rpsgame.py", line 21, in main\n    play_game("You", "Computer")\n  File "/python-for-absolute-beginners-course/code/07-data-structures/rocks-game/rpsgame.py", line 36, in play_game\n    roll1 = get_roll(player_1, roll_names)\n  File "/python-for-absolute-beginners-course/code/07-data-structures/rocks-game/rpsgame.py", line 91, in get_roll\n    text = input(f"{player_name}, what is your roll? ")\nEOFError: EOF when reading a line\n'
2021-03-29 21:48:56,517 [ERROR]  <proc0> python-for-absolute-beginners-course: Success
2021-03-29 21:49:00,118 [ERROR]  <proc0> lambda-networks: BuildFailed
2021-03-29 21:49:05,545 [ERROR]  <proc0> dimensionality_reduction_alo_codes: BuildFailed
2021-03-29 21:54:01,592 [INFO]  <proc0> pytorch-openai-transformer-lm: Success
2021-03-29 21:54:18,864 [ERROR]  <proc0> finetune-transformer-lm: BuildFailed
2021-03-29 21:54:29,185 [INFO]  <proc0> data-science-blogs: Success
2021-03-29 21:54:58,977 [ERROR]  Command 'None' in image 'sha256:ed62961bc93ef72255b547a7c9bc6baa27d732537ed615315ca90fa47ea5800c' returned non-zero exit status 1: b'Traceback (most recent call last):\n  File "/SSRSpeed/main.py", line 78, in <module>\n    input("Press ENTER to conitnue or Crtl+C to exit.")\nEOFError: EOF when reading a line\n'
2021-03-29 21:54:58,977 [ERROR]  <proc0> SSRSpeed: Success
2021-03-29 21:55:17,945 [ERROR]  Command 'None' in image 'sha256:7efd0dfecd66009f62b36b34e57d41cea2bc54c6b41f7dec3c0abe4b64f67000' returned non-zero exit status 1: b'Traceback (most recent call last):\n  File "/dirsearch/dirsearch.py", line 27, in <module>\n    from lib.core import ArgumentParser\n  File "/dirsearch/lib/core/__init__.py", line 3, in <module>\n    from .fuzzer import *  # noqa: F401\n  File "/dirsearch/lib/core/fuzzer.py", line 22, in <module>\n    from lib.connection.request_exception import RequestException\n  File "/dirsearch/lib/connection/__init__.py", line 2, in <module>\n    from .requester import *  # noqa: F401\n  File "/dirsearch/lib/connection/requester.py", line 24, in <module>\n    import thirdparty.requests as requests\n  File "/dirsearch/thirdparty/requests/__init__.py", line 43, in <module>\n    import urllib3\nModuleNotFoundError: No module named \'urllib3\'\n'
2021-03-29 21:55:17,945 [ERROR]  <proc0> dirsearch: RunFailed
2021-03-29 21:56:12,824 [ERROR]  Command 'None' in image 'sha256:846627e80609a1598b49b8b4536d65b06346eb5e23029a77aaa908d97f4a8f86' returned non-zero exit status 1: b'Traceback (most recent call last):\n  File "/usr/local/lib/python3.9/site-packages/impacket/dcerpc/v5/transport.py", line 346, in connect\n    self.__socket.connect(sa)\nsocket.timeout: timed out\n\nDuring handling of the above exception, another exception occurred:\n\nTraceback (most recent call last):\n  File "/CVE-2020-1472/./zerologon_tester.py", line 86, in <module>\n    perform_attack(\'\\\\\\\\\' + dc_name, dc_ip, dc_name)\n  File "/CVE-2020-1472/./zerologon_tester.py", line 62, in perform_attack\n    rpc_con = try_zero_authenticate(dc_handle, dc_ip, target_computer)\n  File "/CVE-2020-1472/./zerologon_tester.py", line 22, in try_zero_authenticate\n    binding = epm.hept_map(dc_ip, nrpc.MSRPC_UUID_NRPC, protocol=\'ncacn_ip_tcp\')\n  File "/usr/local/lib/python3.9/site-packages/impacket/dcerpc/v5/epm.py", line 1256, in hept_map\n    dce.connect()\n  File "/usr/local/lib/python3.9/site-packages/impacket/dcerpc/v5/rpcrt.py", line 801, in connect\n    return self._transport.connect()\n  File "/usr/local/lib/python3.9/site-packages/impacket/dcerpc/v5/transport.py", line 349, in connect\n    raise DCERPCException("Could not connect: %s" % msg)\nimpacket.dcerpc.v5.rpcrt.DCERPCException: Could not connect: timed out\n'
2021-03-29 21:56:12,824 [ERROR]  <proc0> CVE-2020-1472: Success
2021-03-29 21:57:36,358 [INFO]  <proc0> 30-Days-Of-Python: Success
2021-03-29 21:57:47,675 [ERROR]  <proc0> Vxscan: BuildFailed
2021-03-29 21:57:49,766 [ERROR]  <proc0> mnssp3-DNA: BuildFailed
2021-03-29 21:57:51,814 [ERROR]  <proc0> mnssp3-EMR: BuildFailed
2021-03-29 21:58:50,304 [ERROR]  Command 'None' in image 'sha256:964dac7f135b007c68e9d687d93c70ce0467aab787cd8f7086eb6ce6ca8d8c77' returned non-zero exit status 1: b'Traceback (most recent call last):\n  File "/usr/local/lib/python3.9/site-packages/keras/__init__.py", line 3, in <module>\n    from tensorflow.keras.layers.experimental.preprocessing import RandomRotation\nModuleNotFoundError: No module named \'tensorflow\'\n\nDuring handling of the above exception, another exception occurred:\n\nTraceback (most recent call last):\n  File "/mnssp3-EEG/EEG/EpilepsyDetection/Python/EEG/predict.py", line 7, in <module>\n    from keras.models import Sequential \n  File "/usr/local/lib/python3.9/site-packages/keras/__init__.py", line 5, in <module>\n    raise ImportError(\nImportError: Keras requires TensorFlow 2.2 or higher. Install TensorFlow via `pip install tensorflow`\n'
2021-03-29 21:58:50,305 [ERROR]  <proc0> mnssp3-EEG: RunFailed
2021-03-29 22:01:55,651 [INFO]  <proc0> proxylessnas: Success
2021-03-29 22:04:08,998 [INFO]  <proc0> sweetviz: Success
2021-03-29 22:04:27,391 [INFO]  <proc0> policy_sentry: Success
2021-03-29 22:04:35,343 [ERROR]  Command 'None' in image 'sha256:c17c25fabddf9fdc68bead92dfb6c8ce1858be8f0ddc48add20f91853e155ef9' returned non-zero exit status 2: b'usage: noisy.py [-h] [--log -l] --config -c [--timeout -t]\nnoisy.py: error: the following arguments are required: --config\n'
2021-03-29 22:04:35,343 [ERROR]  <proc0> noisy: Success
2021-03-29 22:06:48,198 [ERROR]  <proc0> pytorch-meta: BuildFailed
2021-03-29 22:07:10,650 [INFO]  <proc0> links-uteis: Success
2021-03-29 22:07:42,585 [INFO]  <proc0> WeblogicScan: Success
2021-03-29 22:09:02,868 [INFO]  <proc0> heartrate: Success
2021-03-29 22:09:13,334 [ERROR]  Command 'None' in image 'sha256:0713fd04437f815e40cb21ff9843ac592e365cb9f9c4a828fc1905a8d966917f' returned non-zero exit status 1: b'Traceback (most recent call last):\n  File "/gitGraber/gitGraber.py", line 358, in <module>\n    monitor()\n  File "/gitGraber/gitGraber.py", line 39, in monitor\n    my_cron = CronTab(user=True)\n  File "/usr/local/lib/python3.9/site-packages/crontab.py", line 228, in __init__\n    self.read(tabfile)\n  File "/usr/local/lib/python3.9/site-packages/crontab.py", line 291, in read\n    (out, err) = open_pipe(CRONCMD, l=\'\', **self.user_opt).communicate()\n  File "/usr/local/lib/python3.9/site-packages/crontab.py", line 190, in open_pipe\n    return sp.Popen(args, stdout=sp.PIPE, stderr=sp.PIPE, env=env)\n  File "/usr/local/lib/python3.9/subprocess.py", line 947, in __init__\n    self._execute_child(args, executable, preexec_fn, close_fds,\n  File "/usr/local/lib/python3.9/subprocess.py", line 1819, in _execute_child\n    raise child_exception_type(errno_num, err_msg, err_filename)\nFileNotFoundError: [Errno 2] No such file or directory: \'/usr/bin/crontab\'\n'
2021-03-29 22:09:13,334 [ERROR]  <proc0> gitGraber: Success
2021-03-29 22:10:58,803 [ERROR]  Command 'None' in image 'sha256:b9f904a6d03471ecc7c239fb95358b738ad7db0184c908a0c626295ca670e579' returned non-zero exit status 1: b'Traceback (most recent call last):\n  File "/karateclub/test.py", line 2, in <module>\n    from karateclub import EgoNetSplitter\n  File "/karateclub/karateclub/__init__.py", line 2, in <module>\n    from karateclub.node_embedding import *\n  File "/karateclub/karateclub/node_embedding/__init__.py", line 1, in <module>\n    from .neighbourhood import *\n  File "/karateclub/karateclub/node_embedding/neighbourhood/__init__.py", line 2, in <module>\n    from .deepwalk import DeepWalk\n  File "/karateclub/karateclub/node_embedding/neighbourhood/deepwalk.py", line 3, in <module>\n    from gensim.models.word2vec import Word2Vec\n  File "/usr/local/lib/python3.9/site-packages/gensim/__init__.py", line 5, in <module>\n    from gensim import parsing, corpora, matutils, interfaces, models, similarities, summarization, utils  # noqa:F401\n  File "/usr/local/lib/python3.9/site-packages/gensim/corpora/__init__.py", line 6, in <module>\n    from .indexedcorpus import IndexedCorpus  # noqa:F401 must appear before the other classes\n  File "/usr/local/lib/python3.9/site-packages/gensim/corpora/indexedcorpus.py", line 15, in <module>\n    from gensim import interfaces, utils\n  File "/usr/local/lib/python3.9/site-packages/gensim/interfaces.py", line 21, in <module>\n    from gensim import utils, matutils\n  File "/usr/local/lib/python3.9/site-packages/gensim/matutils.py", line 1104, in <module>\n    from gensim._matutils import logsumexp, mean_absolute_difference, dirichlet_expectation\n  File ".eggs/Cython-0.29.14-py2.7-linux-x86_64.egg/Cython/Includes/numpy/__init__.pxd", line 242, in init gensim._matutils\nValueError: numpy.ndarray size changed, may indicate binary incompatibility. Expected 88 from C header, got 80 from PyObject\n'
2021-03-29 22:10:58,804 [ERROR]  <proc0> karateclub: ImportError
2021-03-29 22:11:06,993 [ERROR]  <proc0> archivy: BuildFailed
2021-03-29 22:11:12,739 [ERROR]  <proc0> gcn: BuildFailed
2021-03-29 22:16:02,345 [ERROR]  Command 'None' in image 'sha256:7510ac3d45ab486c60fc447702b81e226bc656573fe3efcce41bbe2eee2aaf32' returned non-zero exit status 1: b'Traceback (most recent call last):\n  File "/leedeeprl-notes/codes/A2C/main.py", line 17, in <module>\n    from torch.utils.tensorboard import SummaryWriter\n  File "/usr/local/lib/python3.9/site-packages/torch/utils/tensorboard/__init__.py", line 1, in <module>\n    import tensorboard\nModuleNotFoundError: No module named \'tensorboard\'\n'
2021-03-29 22:16:02,345 [ERROR]  <proc0> leedeeprl-notes: RunFailed
2021-03-29 22:17:31,115 [INFO]  <proc0> django-vue-template: Success
2021-03-29 22:18:26,268 [INFO]  <proc0> GScan: Success
2021-03-29 22:18:48,406 [INFO]  <proc0> distribution-is-all-you-need: Success
2021-03-29 22:26:17,235 [INFO]  <proc0> flops-counter.pytorch: Success
2021-03-29 22:26:30,856 [ERROR]  Command 'None' in image 'sha256:6901b64b17843e1c108542485bbbd44352090485505bd27b7147088f095afefa' returned non-zero exit status 1: b'Warning: Output is not to a terminal (fd=1).\nWarning: Input is not to a terminal (fd=0).\nTraceback (most recent call last):\n  File "/PyInquirer/test.py", line 12, in <module>\n    answers = prompt.prompt(questions)\n  File "/PyInquirer/PyInquirer/prompt.py", line 71, in prompt\n    result = getattr(prompts, type_).question(message, **_kwargs)\n  File "/PyInquirer/PyInquirer/prompts/input.py", line 44, in question\n    return prompt(\n  File "/usr/local/lib/python3.9/site-packages/prompt_toolkit/shortcuts/prompt.py", line 904, in prompt\n    return session.prompt(*a, **kw)\n  File "/usr/local/lib/python3.9/site-packages/prompt_toolkit/shortcuts/prompt.py", line 797, in prompt\n    return run_sync()\n  File "/usr/local/lib/python3.9/site-packages/prompt_toolkit/shortcuts/prompt.py", line 786, in run_sync\n    return self.app.run(inputhook=self.inputhook, pre_run=pre_run2)\n  File "/usr/local/lib/python3.9/site-packages/prompt_toolkit/application/application.py", line 736, in run\n    return run()\n  File "/usr/local/lib/python3.9/site-packages/prompt_toolkit/application/application.py", line 710, in run\n    return f.result()\n  File "/usr/local/lib/python3.9/site-packages/prompt_toolkit/eventloop/future.py", line 151, in result\n    raise self._exception\n  File "/usr/local/lib/python3.9/site-packages/prompt_toolkit/eventloop/coroutine.py", line 92, in step_next\n    new_f = coroutine.throw(exc)\n  File "/usr/local/lib/python3.9/site-packages/prompt_toolkit/application/application.py", line 685, in _run_async2\n    result = yield f\n  File "/usr/local/lib/python3.9/site-packages/prompt_toolkit/eventloop/coroutine.py", line 88, in step_next\n    new_f = coroutine.send(None)\n  File "/usr/local/lib/python3.9/site-packages/prompt_toolkit/application/application.py", line 625, in _run_async\n    with self.input.attach(read_from_input):\n  File "/usr/local/lib/python3.9/contextlib.py", line 117, in __enter__\n    return next(self.gen)\n  File "/usr/local/lib/python3.9/site-packages/prompt_toolkit/input/vt100.py", line 150, in _attached_input\n    loop.add_reader(fd, callback)\n  File "/usr/local/lib/python3.9/site-packages/prompt_toolkit/eventloop/posix.py", line 273, in add_reader\n    self.selector.register(fd)\n  File "/usr/local/lib/python3.9/site-packages/prompt_toolkit/eventloop/select.py", line 78, in register\n    sel.register(fd)\n  File "/usr/local/lib/python3.9/site-packages/prompt_toolkit/eventloop/select.py", line 133, in register\n    self._sel.register(fd, selectors.EVENT_READ, None)\n  File "/usr/local/lib/python3.9/selectors.py", line 360, in register\n    self._selector.register(key.fd, poller_events)\nPermissionError: [Errno 1] Operation not permitted\n'
2021-03-29 22:26:30,856 [ERROR]  <proc0> PyInquirer: Success
2021-03-29 22:26:36,911 [ERROR]  <proc0> sparse_attention: BuildFailed
2021-03-29 22:31:24,561 [ERROR]  <proc0> micronet: BuildFailed
2021-03-29 22:33:44,287 [ERROR]  <proc0> machine_learning_examples: BuildFailed
2021-03-29 22:34:07,835 [INFO]  <proc0> BlueKeep: Success
2021-03-29 22:34:38,194 [ERROR]  Command 'None' in image 'sha256:dc345c8955ffcbb026fe4c12d0311b4769192abe3c35069814799a90431049e1' returned non-zero exit status 1: b'Getting uuid of QR code.\nDownloading QR code.\nTraceback (most recent call last):\n  File "/wechat_friends/get_user_info.py", line 49, in <module>\n    itchat.auto_login()\n  File "/usr/local/lib/python3.9/site-packages/itchat/components/register.py", line 35, in auto_login\n    self.login(enableCmdQR=enableCmdQR, picDir=picDir, qrCallback=qrCallback,\n  File "/usr/local/lib/python3.9/site-packages/itchat/components/login.py", line 48, in login\n    qrStorage = self.get_QR(enableCmdQR=enableCmdQR,\n  File "/usr/local/lib/python3.9/site-packages/itchat/components/login.py", line 123, in get_QR\n    utils.print_qr(picDir)\n  File "/usr/local/lib/python3.9/site-packages/itchat/utils.py", line 83, in print_qr\n    subprocess.call([\'xdg-open\', fileDir])\n  File "/usr/local/lib/python3.9/subprocess.py", line 349, in call\n    with Popen(*popenargs, **kwargs) as p:\n  File "/usr/local/lib/python3.9/subprocess.py", line 947, in __init__\n    self._execute_child(args, executable, preexec_fn, close_fds,\n  File "/usr/local/lib/python3.9/subprocess.py", line 1819, in _execute_child\n    raise child_exception_type(errno_num, err_msg, err_filename)\nFileNotFoundError: [Errno 2] No such file or directory: \'xdg-open\'\n'
2021-03-29 22:34:38,194 [ERROR]  <proc0> wechat_friends: Success
2021-03-29 22:34:48,671 [ERROR]  <proc0> petastorm: BuildFailed
2021-03-29 22:35:21,477 [ERROR]  Command 'None' in image 'sha256:15463e4598c92f3958ef1e8184f44820a15dee33ae0990ca4cc3a1a768786591' returned non-zero exit status 1: b'Traceback (most recent call last):\n  File "/blackhat-python3/chapter04/pic_carver.py", line 1, in <module>\n    import cv2\n  File "/usr/local/lib/python3.9/site-packages/cv2/__init__.py", line 5, in <module>\n    from .cv2 import *\nImportError: libGL.so.1: cannot open shared object file: No such file or directory\n'
2021-03-29 22:35:21,477 [ERROR]  <proc0> blackhat-python3: RunFailed
2021-03-29 22:35:27,672 [ERROR]  <proc0> neural_prophet: BuildFailed
2021-03-29 22:35:39,210 [INFO]  <proc0> pyp: Success
2021-03-29 22:35:45,810 [ERROR]  <proc0> SimpleHTR: BuildFailed
2021-03-29 22:39:49,048 [ERROR]  Command 'None' in image 'sha256:0a46404ede80e54caf2288516ca4b8b607280ac1b5a38362b48510e15658670e' returned non-zero exit status 1: b'Traceback (most recent call last):\n  File "/SuperGluePretrainedNetwork/match_pairs.py", line 56, in <module>\n    from models.utils import (compute_pose_error, compute_epipolar_error,\n  File "/SuperGluePretrainedNetwork/models/utils.py", line 50, in <module>\n    import cv2\n  File "/usr/local/lib/python3.9/site-packages/cv2/__init__.py", line 5, in <module>\n    from .cv2 import *\nImportError: libGL.so.1: cannot open shared object file: No such file or directory\n'
2021-03-29 22:39:49,048 [ERROR]  <proc0> SuperGluePretrainedNetwork: RunFailed
2021-03-29 22:43:26,901 [ERROR]  Command 'None' in image 'sha256:e323652b9f3a060f1d8988145694b4710c33d023a586c410236300052ebf6836' returned non-zero exit status 1: b'Traceback (most recent call last):\n  File "/SuperPointPretrainedNetwork/./demo_superpoint.py", line 53, in <module>\n    import cv2\n  File "/usr/local/lib/python3.9/site-packages/cv2/__init__.py", line 5, in <module>\n    from .cv2 import *\nImportError: libGL.so.1: cannot open shared object file: No such file or directory\n'
2021-03-29 22:43:26,901 [ERROR]  <proc0> SuperPointPretrainedNetwork: RunFailed
2021-03-29 22:43:48,028 [ERROR]  <proc0> pydub: BuildFailed
2021-03-29 22:43:54,565 [ERROR]  <proc0> efficientnet: BuildFailed
2021-03-29 22:43:55,218 [ERROR]  <proc0> tensorflow-yolov3: BuildFailed
2021-03-29 22:44:02,948 [ERROR]  <proc0> BERT-BiLSTM-CRF-NER: BuildFailed
2021-03-29 22:44:13,789 [ERROR]  <proc0> mars: BuildFailed
2021-03-29 22:44:20,125 [ERROR]  <proc0> jina: BuildFailed
2021-03-29 22:44:36,566 [INFO]  <proc0> starlette: Success
2021-03-29 22:44:36,566 [INFO]  55/100, 0.55
2021-03-29 22:44:36,566 [INFO]  ----------END----------
