2021-03-08 16:10:37,822 [INFO]  ----------START----------
2021-03-08 16:12:31,202 [ERROR]  Command 'None' in image 'sha256:d287c93fa808a710010485ebab66516dc856d9047c1dcf080dabf9fb5740dda9' returned non-zero exit status 1: b'Traceback (most recent call last):\n  File "gen_tiles.py", line 1, in <module>\n    import cv2 \n  File "/usr/local/lib/python3.8/site-packages/cv2/__init__.py", line 5, in <module>\n    from .cv2 import *\nImportError: libGL.so.1: cannot open shared object file: No such file or directory\n'
2021-03-08 16:12:31,203 [ERROR]  <proc0> tiler: RunFailed
2021-03-08 16:13:06,670 [ERROR]  <proc0> metaflow: BuildFailed
2021-03-08 16:13:39,946 [INFO]  <proc0> tinygrad: Success
2021-03-08 16:14:48,613 [ERROR]  <proc0> sktime: BuildFailed
2021-03-08 16:15:03,396 [INFO]  <proc0> scalene: Success
2021-03-08 16:16:21,746 [INFO]  <proc0> Python-crawler-tutorial-starts-from-zero: Success
2021-03-08 16:16:35,106 [INFO]  <proc0> jd-assistant: Success
2021-03-08 16:16:54,530 [INFO]  <proc0> autoscraper: Success
2021-03-08 16:17:01,380 [INFO]  <proc0> bullet: Success
2021-03-08 16:17:17,930 [INFO]  <proc0> pipx: Success
2021-03-08 16:20:11,423 [INFO]  <proc0> DeepLearning: Success
2021-03-08 16:20:27,664 [ERROR]  <proc0> OneForAll: BuildFailed
2021-03-08 16:20:35,223 [ERROR]  Command 'None' in image 'sha256:782a7d131200a1f96acc9cafad5927acbe8ea84f66153155872ef7f79b9118a2' returned non-zero exit status 1: b'Traceback (most recent call last):\n  File "learn_math_fast/build_toc.py", line 67, in <module>\n    gen_toc(filename)\n  File "learn_math_fast/build_toc.py", line 53, in gen_toc\n    md = _read_md(filename)\n  File "learn_math_fast/build_toc.py", line 48, in _read_md\n    with open(filename, \'r\') as f:\nFileNotFoundError: [Errno 2] No such file or directory: \'README.md\'\n'
2021-03-08 16:20:35,223 [ERROR]  <proc0> learn_math_fast: Success
2021-03-08 16:22:37,709 [INFO]  <proc0> akshare: Success
2021-03-08 16:22:54,658 [ERROR]  Command 'None' in image 'sha256:9d89bb8c1100fdf43c9ad4b858e6984b9f1396b4c2298441d547e86265d708ae' returned non-zero exit status 1: b'Traceback (most recent call last):\n  File "Summer2021-Internships/sync.py", line 36, in <module>\n    html = parse_markdown_to_html_table()\n  File "Summer2021-Internships/sync.py", line 9, in parse_markdown_to_html_table\n    readme = open("README.md", \'r\').read()\nFileNotFoundError: [Errno 2] No such file or directory: \'README.md\'\n'
2021-03-08 16:22:54,658 [ERROR]  <proc0> Summer2021-Internships: Success
2021-03-08 16:27:55,592 [ERROR]  <proc0> koalas: BuildFailed
2021-03-08 16:28:22,009 [ERROR]  <proc0> kb: RunFailed
2021-03-08 16:30:19,860 [ERROR]  <proc0> ResNeSt: BuildFailed
2021-03-08 16:32:03,466 [INFO]  <proc0> ECommerceCrawlers-TouTiao: Success
2021-03-08 16:33:56,896 [INFO]  <proc0> ECommerceCrawlers-East_money: Success
2021-03-08 16:48:37,355 [INFO]  <proc0> RAdam: Success
2021-03-08 16:48:54,595 [INFO]  <proc0> newscatcher: Success
2021-03-08 16:49:23,060 [INFO]  <proc0> GitHub520: Success
2021-03-08 16:49:23,385 [ERROR]  <proc0> vit-pytorch: BuildFailed
2021-03-08 17:05:15,428 [ERROR]  Command 'None' in image 'sha256:0741dee8326d6002ffa1f89b1e7151cd2013f06b1f5262ddeba8082de95cf8f5' returned non-zero exit status 1: b'Traceback (most recent call last):\n  File "run.py", line 41, in <module>\n    dataset = Human36mDataset(dataset_path)\n  File "/VideoPose3D/common/h36m_dataset.py", line 234, in __init__\n    data = np.load(path, allow_pickle=True)[\'positions_3d\'].item()\n  File "/usr/local/lib/python3.8/site-packages/numpy/lib/npyio.py", line 416, in load\n    fid = stack.enter_context(open(os_fspath(file), "rb"))\nFileNotFoundError: [Errno 2] No such file or directory: \'data/data_3d_h36m.npz\'\n'
2021-03-08 17:05:15,428 [ERROR]  <proc0> VideoPose3D: Success
2021-03-08 17:05:15,776 [INFO]  <proc0> real-url: Success
2021-03-08 17:05:25,678 [ERROR]  <proc0> clearml: BuildFailed
2021-03-08 17:23:26,712 [INFO]  <proc0> captum: Success
2021-03-08 17:41:04,614 [ERROR]  Command 'None' in image 'sha256:5e53b88708ba61340bd3f13a225db995ee06d8d0d4a800fa82f0383a6fba2c8c' returned non-zero exit status 1: b'Traceback (most recent call last):\n  File "main.py", line 1, in <module>\n    from UGATIT import UGATIT\n  File "/UGATIT-pytorch/UGATIT.py", line 6, in <module>\n    from utils import *\n  File "/UGATIT-pytorch/utils.py", line 2, in <module>\n    import os, cv2, torch\n  File "/usr/local/lib/python3.8/site-packages/cv2/__init__.py", line 5, in <module>\n    from .cv2 import *\nImportError: libGL.so.1: cannot open shared object file: No such file or directory\n'
2021-03-08 17:41:04,615 [ERROR]  <proc0> UGATIT-pytorch: RunFailed
2021-03-08 17:41:08,989 [ERROR]  <proc0> arxiv-latex-cleaner: BuildFailed
2021-03-08 17:41:52,003 [INFO]  <proc0> GeneralNewsExtractor: Success
2021-03-08 17:42:06,599 [ERROR]  Command 'None' in image 'sha256:f06851a6c2d869b3644ce1187b4cd97179680998398ba57220bf7da8671117a8' returned non-zero exit status 1: b'Traceback (most recent call last):\n  File "main.py", line 12, in <module>\n    crawler.run()\n  File "/DXY-COVID-19-Crawler/service/crawler.py", line 31, in run\n    self.crawler()\n  File "/DXY-COVID-19-Crawler/service/crawler.py", line 46, in crawler\n    soup = BeautifulSoup(r.content, \'lxml\')\n  File "/usr/local/lib/python3.8/site-packages/bs4/__init__.py", line 243, in __init__\n    raise FeatureNotFound(\nbs4.FeatureNotFound: Couldn\'t find a tree builder with the features you requested: lxml. Do you need to install a parser library?\n'
2021-03-08 17:42:06,600 [ERROR]  <proc0> DXY-COVID-19-Crawler: ImportError
2021-03-08 18:06:12,425 [INFO]  <proc0> facenet-pytorch: Success
2021-03-08 18:06:20,695 [ERROR]  Command 'None' in image 'sha256:27f3df4b8cd2ce5403416b483c660db6ca96cfe364779121de13e1fd4d5575b9' returned non-zero exit status 1: b"\n*******************************************************************************\ntest.py\n19 <module>\n    exception_file_color=pretty_errors.BRIGHT_BLUE\n)\nirrelevant = pretty_errors.config.copy()\nirrelevant.line_color = irrelevant.code_color = irrelevant.filename_color = irrelevant.function_color = irrelevant.line_number_color = (\n    pretty_errors.GREY\n)\npretty_errors.pathed_config(irrelevant, 'c:/python', 'c:/users')\n\n\nimport os\nos.rename('nofile', 'stillnofile')\n\nFileNotFoundError:\n2\nNo such file or directory\nnofile\nstillnofile\n"
2021-03-08 18:06:20,695 [ERROR]  <proc0> PrettyErrors: Success
2021-03-08 18:07:11,513 [INFO]  <proc0> m2cgen: Success
2021-03-08 18:07:11,874 [ERROR]  <proc0> dirmap: RunFailed
2021-03-08 18:07:15,936 [ERROR]  <proc0> latexify_py: BuildFailed
2021-03-08 18:07:45,576 [ERROR]  Command 'None' in image 'sha256:cb093c5e91fb4c83a55fb96166e40a15f242c80f2486dba4e558e006f5e0bbb6' returned non-zero exit status 1: b'Traceback (most recent call last):\n  File "main.py", line 48, in <module>\n    books = pd.read_excel(table_url)\n  File "/usr/local/lib/python3.8/site-packages/pandas/util/_decorators.py", line 299, in wrapper\n    return func(*args, **kwargs)\n  File "/usr/local/lib/python3.8/site-packages/pandas/io/excel/_base.py", line 336, in read_excel\n    io = ExcelFile(io, storage_options=storage_options, engine=engine)\n  File "/usr/local/lib/python3.8/site-packages/pandas/io/excel/_base.py", line 1114, in __init__\n    self._reader = self._engines[engine](self._io, storage_options=storage_options)\n  File "/usr/local/lib/python3.8/site-packages/pandas/io/excel/_xlrd.py", line 24, in __init__\n    import_optional_dependency("xlrd", extra=err_msg)\n  File "/usr/local/lib/python3.8/site-packages/pandas/compat/_optional.py", line 109, in import_optional_dependency\n    raise ImportError(msg) from None\nImportError: Missing optional dependency \'xlrd\'. Install xlrd >= 1.0.0 for Excel support Use pip or conda to install xlrd.\n'
2021-03-08 18:07:45,577 [ERROR]  <proc0> springer_free_books: RunFailed
2021-03-08 18:08:44,135 [INFO]  <proc0> stumpy: Success
2021-03-08 18:13:23,458 [INFO]  <proc0> SegLoss: Success
2021-03-08 18:13:31,206 [INFO]  <proc0> coding-problems: Success
2021-03-08 18:13:42,658 [INFO]  <proc0> dongbei: Success
2021-03-08 18:13:55,038 [INFO]  <proc0> returns: Success
2021-03-08 18:14:09,247 [INFO]  <proc0> xxh: Success
2021-03-08 18:14:17,563 [ERROR]  <proc0> apistar: RunFailed
2021-03-08 19:00:45,228 [ERROR]  <proc0> pandarallel: BuildFailed
2021-03-08 19:00:46,380 [ERROR]  <proc0> DecryptLogin: RunFailed
2021-03-08 19:01:13,535 [ERROR]  <proc0> webpy: BuildFailed
2021-03-08 19:01:50,321 [INFO]  <proc0> SSRFmap: Success
2021-03-08 19:01:58,622 [ERROR]  Command 'None' in image 'sha256:f1feec15b47de4b9a2235990a383a78c3a06d70f00eb9f342d2195accd21e2b4' returned non-zero exit status 1: b'Traceback (most recent call last):\n  File "code/07-data-structures/rocks-game/rpsgame.py", line 102, in <module>\n    main()\n  File "code/07-data-structures/rocks-game/rpsgame.py", line 21, in main\n    play_game("You", "Computer")\n  File "code/07-data-structures/rocks-game/rpsgame.py", line 36, in play_game\n    roll1 = get_roll(player_1, roll_names)\n  File "code/07-data-structures/rocks-game/rpsgame.py", line 91, in get_roll\n    text = input(f"{player_name}, what is your roll? ")\nEOFError: EOF when reading a line\n'
2021-03-08 19:01:58,622 [ERROR]  <proc0> python-for-absolute-beginners-course: Success
2021-03-08 19:08:56,368 [INFO]  <proc0> lambda-networks: Success
2021-03-08 19:12:10,064 [INFO]  <proc0> dimensionality_reduction_alo_codes: Success
2021-03-08 19:17:34,645 [INFO]  <proc0> pytorch-openai-transformer-lm: Success
2021-03-08 19:22:59,297 [INFO]  <proc0> finetune-transformer-lm: Success
2021-03-08 19:23:18,626 [INFO]  <proc0> data-science-blogs: Success
2021-03-08 19:23:47,394 [ERROR]  Command 'None' in image 'sha256:171d026399aa0a98dbef89f512ccf407da3a448224798df2988014aa1b59811a' returned non-zero exit status 1: b'Traceback (most recent call last):\n  File "main.py", line 78, in <module>\n    input("Press ENTER to conitnue or Crtl+C to exit.")\nEOFError: EOF when reading a line\n'
2021-03-08 19:23:47,394 [ERROR]  <proc0> SSRSpeed: Success
2021-03-08 19:27:50,552 [ERROR]  <proc0> dirsearch: RunFailed
2021-03-08 19:28:47,227 [ERROR]  Command 'None' in image 'sha256:8536c5bd77357b666d11513393b15645dfe9be0db032bbb13da43822cfea5d4f' returned non-zero exit status 1: b'Traceback (most recent call last):\n  File "/usr/local/lib/python3.8/site-packages/impacket/dcerpc/v5/transport.py", line 346, in connect\n    self.__socket.connect(sa)\nsocket.timeout: timed out\n\nDuring handling of the above exception, another exception occurred:\n\nTraceback (most recent call last):\n  File "./zerologon_tester.py", line 86, in <module>\n    perform_attack(\'\\\\\\\\\' + dc_name, dc_ip, dc_name)\n  File "./zerologon_tester.py", line 62, in perform_attack\n    rpc_con = try_zero_authenticate(dc_handle, dc_ip, target_computer)\n  File "./zerologon_tester.py", line 22, in try_zero_authenticate\n    binding = epm.hept_map(dc_ip, nrpc.MSRPC_UUID_NRPC, protocol=\'ncacn_ip_tcp\')\n  File "/usr/local/lib/python3.8/site-packages/impacket/dcerpc/v5/epm.py", line 1256, in hept_map\n    dce.connect()\n  File "/usr/local/lib/python3.8/site-packages/impacket/dcerpc/v5/rpcrt.py", line 801, in connect\n    return self._transport.connect()\n  File "/usr/local/lib/python3.8/site-packages/impacket/dcerpc/v5/transport.py", line 349, in connect\n    raise DCERPCException("Could not connect: %s" % msg)\nimpacket.dcerpc.v5.rpcrt.DCERPCException: Could not connect: timed out\n'
2021-03-08 19:28:47,228 [ERROR]  <proc0> CVE-2020-1472: Success
2021-03-08 19:28:51,772 [INFO]  <proc0> 30-Days-Of-Python: Success
2021-03-08 19:29:03,882 [ERROR]  <proc0> Vxscan: BuildFailed
2021-03-08 19:29:06,121 [ERROR]  <proc0> mnssp3-DNA: BuildFailed
2021-03-08 19:29:08,194 [ERROR]  <proc0> mnssp3-EMR: BuildFailed
2021-03-08 19:30:15,491 [ERROR]  Command 'None' in image 'sha256:b14e2bb42bd0e3a7c7292597523bcfc83d67afa4c57cd7a7ecb83e7746dd4cf3' returned non-zero exit status 1: b'Traceback (most recent call last):\n  File "/usr/local/lib/python3.8/site-packages/keras/__init__.py", line 3, in <module>\n    from tensorflow.keras.layers.experimental.preprocessing import RandomRotation\nModuleNotFoundError: No module named \'tensorflow\'\n\nDuring handling of the above exception, another exception occurred:\n\nTraceback (most recent call last):\n  File "predict.py", line 7, in <module>\n    from keras.models import Sequential \n  File "/usr/local/lib/python3.8/site-packages/keras/__init__.py", line 5, in <module>\n    raise ImportError(\nImportError: Keras requires TensorFlow 2.2 or higher. Install TensorFlow via `pip install tensorflow`\n'
2021-03-08 19:30:15,491 [ERROR]  <proc0> mnssp3-EEG: RunFailed
2021-03-08 19:34:11,060 [INFO]  <proc0> proxylessnas: Success
2021-03-08 19:36:26,308 [INFO]  <proc0> sweetviz: Success
2021-03-08 19:36:50,608 [INFO]  <proc0> policy_sentry: Success
2021-03-08 19:37:00,924 [ERROR]  Command 'None' in image 'sha256:e08d021637afda365ebc6fe102f1af89b70ebcf2896f716c58181b21b4082685' returned non-zero exit status 2: b'usage: noisy.py [-h] [--log -l] --config -c [--timeout -t]\nnoisy.py: error: the following arguments are required: --config\n'
2021-03-08 19:37:00,925 [ERROR]  <proc0> noisy: Success
2021-03-08 19:40:36,091 [ERROR]  <proc0> pytorch-meta: BuildFailed
2021-03-08 19:41:01,848 [INFO]  <proc0> links-uteis: Success
2021-03-08 19:41:22,528 [INFO]  <proc0> WeblogicScan: Success
2021-03-08 19:42:43,944 [INFO]  <proc0> heartrate: Success
2021-03-08 19:42:54,587 [ERROR]  Command 'None' in image 'sha256:0e13261acec7060c72beb58c86d69f0832a01dc5230595a7873b468f50d72d14' returned non-zero exit status 1: b'Traceback (most recent call last):\n  File "gitGraber.py", line 358, in <module>\n    monitor()\n  File "gitGraber.py", line 39, in monitor\n    my_cron = CronTab(user=True)\n  File "/usr/local/lib/python3.8/site-packages/crontab.py", line 228, in __init__\n    self.read(tabfile)\n  File "/usr/local/lib/python3.8/site-packages/crontab.py", line 291, in read\n    (out, err) = open_pipe(CRONCMD, l=\'\', **self.user_opt).communicate()\n  File "/usr/local/lib/python3.8/site-packages/crontab.py", line 190, in open_pipe\n    return sp.Popen(args, stdout=sp.PIPE, stderr=sp.PIPE, env=env)\n  File "/usr/local/lib/python3.8/subprocess.py", line 854, in __init__\n    self._execute_child(args, executable, preexec_fn, close_fds,\n  File "/usr/local/lib/python3.8/subprocess.py", line 1702, in _execute_child\n    raise child_exception_type(errno_num, err_msg, err_filename)\nFileNotFoundError: [Errno 2] No such file or directory: \'/usr/bin/crontab\'\n'
2021-03-08 19:42:54,587 [ERROR]  <proc0> gitGraber: Success
2021-03-08 19:48:49,652 [ERROR]  Command 'None' in image 'sha256:a58bef6b155e629451fe9630b424c4313892823b957e4a12d7c58e049aa8d18f' returned non-zero exit status 1: b'Traceback (most recent call last):\n  File "test.py", line 8, in <module>\n    splitter.fit(g)\n  File "/karateclub/karateclub/community_detection/overlapping/ego_splitter.py", line 105, in fit\n    self._create_partitions()\n  File "/karateclub/karateclub/community_detection/overlapping/ego_splitter.py", line 87, in _create_partitions\n    self.partitions = community.best_partition(self.persona_graph, resolution=self.resolution, weight=self.weight)\nAttributeError: module \'community\' has no attribute \'best_partition\'\n'
2021-03-08 19:48:49,652 [ERROR]  <proc0> karateclub: Success
2021-03-08 19:48:58,512 [ERROR]  <proc0> archivy: BuildFailed
2021-03-08 19:49:22,722 [INFO]  <proc0> gcn: RunFailed
2021-03-08 19:58:22,247 [ERROR]  Command 'None' in image 'sha256:1c4dd02de8087354c169d5769dcfe963056039050dd6ed55396266c5a4bc3b0c' returned non-zero exit status 1: b'Traceback (most recent call last):\n  File "main.py", line 17, in <module>\n    from torch.utils.tensorboard import SummaryWriter\n  File "/usr/local/lib/python3.8/site-packages/torch/utils/tensorboard/__init__.py", line 1, in <module>\n    import tensorboard\nModuleNotFoundError: No module named \'tensorboard\'\n'
2021-03-08 19:58:22,247 [ERROR]  <proc0> leedeeprl-notes: RunFailed
2021-03-08 19:59:49,819 [INFO]  <proc0> django-vue-template: Success
2021-03-08 20:00:41,830 [INFO]  <proc0> GScan: Success
2021-03-08 20:01:05,625 [INFO]  <proc0> distribution-is-all-you-need: Success
2021-03-08 20:04:37,293 [INFO]  <proc0> flops-counter.pytorch: Success
2021-03-08 20:04:48,317 [ERROR]  Command 'None' in image 'sha256:01dba9c4dff91d809ae4ffd3d31bd091d4664761960cfa8409e65e872aeb9d58' returned non-zero exit status 1: b'Warning: Output is not to a terminal (fd=1).\nWarning: Input is not to a terminal (fd=0).\nTraceback (most recent call last):\n  File "test.py", line 12, in <module>\n    answers = prompt.prompt(questions)\n  File "/PyInquirer/PyInquirer/prompt.py", line 71, in prompt\n    result = getattr(prompts, type_).question(message, **_kwargs)\n  File "/PyInquirer/PyInquirer/prompts/input.py", line 44, in question\n    return prompt(\n  File "/usr/local/lib/python3.8/site-packages/prompt_toolkit/shortcuts/prompt.py", line 904, in prompt\n    return session.prompt(*a, **kw)\n  File "/usr/local/lib/python3.8/site-packages/prompt_toolkit/shortcuts/prompt.py", line 797, in prompt\n    return run_sync()\n  File "/usr/local/lib/python3.8/site-packages/prompt_toolkit/shortcuts/prompt.py", line 786, in run_sync\n    return self.app.run(inputhook=self.inputhook, pre_run=pre_run2)\n  File "/usr/local/lib/python3.8/site-packages/prompt_toolkit/application/application.py", line 736, in run\n    return run()\n  File "/usr/local/lib/python3.8/site-packages/prompt_toolkit/application/application.py", line 710, in run\n    return f.result()\n  File "/usr/local/lib/python3.8/site-packages/prompt_toolkit/eventloop/future.py", line 151, in result\n    raise self._exception\n  File "/usr/local/lib/python3.8/site-packages/prompt_toolkit/eventloop/coroutine.py", line 92, in step_next\n    new_f = coroutine.throw(exc)\n  File "/usr/local/lib/python3.8/site-packages/prompt_toolkit/application/application.py", line 685, in _run_async2\n    result = yield f\n  File "/usr/local/lib/python3.8/site-packages/prompt_toolkit/eventloop/coroutine.py", line 88, in step_next\n    new_f = coroutine.send(None)\n  File "/usr/local/lib/python3.8/site-packages/prompt_toolkit/application/application.py", line 625, in _run_async\n    with self.input.attach(read_from_input):\n  File "/usr/local/lib/python3.8/contextlib.py", line 113, in __enter__\n    return next(self.gen)\n  File "/usr/local/lib/python3.8/site-packages/prompt_toolkit/input/vt100.py", line 150, in _attached_input\n    loop.add_reader(fd, callback)\n  File "/usr/local/lib/python3.8/site-packages/prompt_toolkit/eventloop/posix.py", line 273, in add_reader\n    self.selector.register(fd)\n  File "/usr/local/lib/python3.8/site-packages/prompt_toolkit/eventloop/select.py", line 78, in register\n    sel.register(fd)\n  File "/usr/local/lib/python3.8/site-packages/prompt_toolkit/eventloop/select.py", line 133, in register\n    self._sel.register(fd, selectors.EVENT_READ, None)\n  File "/usr/local/lib/python3.8/selectors.py", line 359, in register\n    self._selector.register(key.fd, poller_events)\nPermissionError: [Errno 1] Operation not permitted\n'
2021-03-08 20:04:48,317 [ERROR]  <proc0> PyInquirer: Success
2021-03-08 20:07:20,257 [ERROR]  Command 'None' in image 'sha256:96146e67aeeccc3fe7fcb51c8ae3c714e386c9c315476b5a04bc2a56ece3d74f' returned non-zero exit status 1: b'2021-03-08 12:07:17.497892: W tensorflow/stream_executor/platform/default/dso_loader.cc:60] Could not load dynamic library \'libcudart.so.11.0\'; dlerror: libcudart.so.11.0: cannot open shared object file: No such file or directory\n2021-03-08 12:07:17.497924: I tensorflow/stream_executor/cuda/cudart_stub.cc:29] Ignore above cudart dlerror if you do not have a GPU set up on your machine.\nTraceback (most recent call last):\n  File "attention.py", line 4, in <module>\n    from blocksparse import BlocksparseTransformer\n  File "/usr/local/lib/python3.8/site-packages/blocksparse/__init__.py", line 3, in <module>\n    from blocksparse.utils import (\n  File "/usr/local/lib/python3.8/site-packages/blocksparse/utils.py", line 15, in <module>\n    data_files_path = tf.resource_loader.get_data_files_path()\nAttributeError: module \'tensorflow\' has no attribute \'resource_loader\'\n'
2021-03-08 20:07:20,257 [ERROR]  <proc0> sparse_attention: ImportError
2021-03-08 20:10:38,681 [ERROR]  <proc0> micronet: BuildFailed
2021-03-08 20:10:47,408 [ERROR]  <proc0> machine_learning_examples: BuildFailed
2021-03-08 20:11:13,966 [INFO]  <proc0> BlueKeep: Success
2021-03-08 20:11:43,065 [ERROR]  Command 'None' in image 'sha256:35caa4afed4464d431caf7b84429d02a6d50ce05da913cb2ad4ef09495909871' returned non-zero exit status 1: b'Getting uuid of QR code.\nDownloading QR code.\nTraceback (most recent call last):\n  File "get_user_info.py", line 49, in <module>\n    itchat.auto_login()\n  File "/usr/local/lib/python3.8/site-packages/itchat/components/register.py", line 35, in auto_login\n    self.login(enableCmdQR=enableCmdQR, picDir=picDir, qrCallback=qrCallback,\n  File "/usr/local/lib/python3.8/site-packages/itchat/components/login.py", line 48, in login\n    qrStorage = self.get_QR(enableCmdQR=enableCmdQR,\n  File "/usr/local/lib/python3.8/site-packages/itchat/components/login.py", line 123, in get_QR\n    utils.print_qr(picDir)\n  File "/usr/local/lib/python3.8/site-packages/itchat/utils.py", line 83, in print_qr\n    subprocess.call([\'xdg-open\', fileDir])\n  File "/usr/local/lib/python3.8/subprocess.py", line 340, in call\n    with Popen(*popenargs, **kwargs) as p:\n  File "/usr/local/lib/python3.8/subprocess.py", line 854, in __init__\n    self._execute_child(args, executable, preexec_fn, close_fds,\n  File "/usr/local/lib/python3.8/subprocess.py", line 1702, in _execute_child\n    raise child_exception_type(errno_num, err_msg, err_filename)\nFileNotFoundError: [Errno 2] No such file or directory: \'xdg-open\'\n'
2021-03-08 20:11:43,066 [ERROR]  <proc0> wechat_friends: Success
2021-03-08 20:12:55,934 [ERROR]  <proc0> petastorm: BuildFailed
2021-03-08 20:13:36,216 [ERROR]  Command 'None' in image 'sha256:79f3fcc4acf5e0922366ce75e77cffcd156f13ef44a210acb81cdda983fc69d1' returned non-zero exit status 1: b'Traceback (most recent call last):\n  File "pic_carver.py", line 1, in <module>\n    import cv2\n  File "/usr/local/lib/python3.8/site-packages/cv2/__init__.py", line 5, in <module>\n    from .cv2 import *\nImportError: libGL.so.1: cannot open shared object file: No such file or directory\n'
2021-03-08 20:13:36,217 [ERROR]  <proc0> blackhat-python3: RunFailed
2021-03-08 20:13:43,256 [ERROR]  <proc0> neural_prophet: BuildFailed
2021-03-08 20:13:43,510 [INFO]  <proc0> pyp: Success
2021-03-08 20:16:46,237 [ERROR]  Command 'None' in image 'sha256:ae126f08d8bd1a8dc434dc5a09a14a8b80179a125d8c9c3837ed7c040d266730' returned non-zero exit status 1: b'Traceback (most recent call last):\n  File "main.py", line 6, in <module>\n    import cv2\n  File "/usr/local/lib/python3.8/site-packages/cv2/__init__.py", line 5, in <module>\n    from .cv2 import *\nImportError: libGL.so.1: cannot open shared object file: No such file or directory\n'
2021-03-08 20:16:46,238 [ERROR]  <proc0> SimpleHTR: RunFailed
2021-03-08 20:20:43,253 [ERROR]  Command 'None' in image 'sha256:1e6d4bca5979274b10bd256d86ffc6abedaac4ff7742bc62c01fd9fa52a5de26' returned non-zero exit status 1: b'Traceback (most recent call last):\n  File "match_pairs.py", line 56, in <module>\n    from models.utils import (compute_pose_error, compute_epipolar_error,\n  File "/SuperGluePretrainedNetwork/models/utils.py", line 50, in <module>\n    import cv2\n  File "/usr/local/lib/python3.8/site-packages/cv2/__init__.py", line 5, in <module>\n    from .cv2 import *\nImportError: libGL.so.1: cannot open shared object file: No such file or directory\n'
2021-03-08 20:20:43,253 [ERROR]  <proc0> SuperGluePretrainedNetwork: RunFailed
2021-03-08 20:24:12,109 [ERROR]  Command 'None' in image 'sha256:781819c2f2f58cc81aa328753ae1c789434435e3c1772c48df84995b2756e0e2' returned non-zero exit status 1: b'Traceback (most recent call last):\n  File "./demo_superpoint.py", line 53, in <module>\n    import cv2\n  File "/usr/local/lib/python3.8/site-packages/cv2/__init__.py", line 5, in <module>\n    from .cv2 import *\nImportError: libGL.so.1: cannot open shared object file: No such file or directory\n'
2021-03-08 20:24:12,109 [ERROR]  <proc0> SuperPointPretrainedNetwork: RunFailed
2021-03-08 20:24:18,523 [ERROR]  <proc0> pydub: BuildFailed
2021-03-08 20:24:27,892 [ERROR]  <proc0> efficientnet: BuildFailed
2021-03-08 20:24:28,595 [ERROR]  <proc0> tensorflow-yolov3: BuildFailed
2021-03-08 20:26:57,874 [ERROR]  <proc0> BERT-BiLSTM-CRF-NER: RunFailed
2021-03-08 20:27:11,212 [ERROR]  <proc0> mars: BuildFailed
2021-03-08 20:27:17,132 [ERROR]  <proc0> jina: BuildFailed
2021-03-08 20:27:33,955 [INFO]  <proc0> starlette: Success
2021-03-08 20:27:33,956 [INFO]  57/100, 0.57
2021-03-08 20:27:33,956 [INFO]  ----------END----------
