2021-03-27 11:09:20,723 [INFO]  ----------START----------
2021-03-27 11:11:35,707 [INFO]  <proc0> tiler: Success
2021-03-27 11:14:03,997 [INFO]  <proc0> metaflow: Success
2021-03-27 11:16:07,186 [INFO]  <proc0> tinygrad: Success
2021-03-27 11:16:18,174 [ERROR]  <proc0> sktime: GenerateFailed
2021-03-27 11:16:55,854 [INFO]  <proc0> scalene: Success
2021-03-27 11:17:49,727 [INFO]  <proc0> Python-crawler-tutorial-starts-from-zero: Success
2021-03-27 11:18:57,559 [INFO]  <proc0> jd-assistant: Success
2021-03-27 11:20:00,372 [INFO]  <proc0> autoscraper: Success
2021-03-27 11:20:26,437 [INFO]  <proc0> bullet: Success
2021-03-27 11:21:03,695 [ERROR]  Command 'None' in image 'sha256:c976f691a965c7e9cfd822baedb4c01fb6b53cd32c3d821e5cd361d2029279f1' returned non-zero exit status 1: b'Traceback (most recent call last):\n  File "/usr/local/bin/pipx", line 5, in <module>\n    from pipx.main import cli\n  File "/usr/local/lib/python3.9/site-packages/pipx/main.py", line 21, in <module>\n    from pipx import commands, constants\n  File "/usr/local/lib/python3.9/site-packages/pipx/commands/__init__.py", line 1, in <module>\n    from pipx.commands.ensure_path import ensure_pipx_paths\n  File "/usr/local/lib/python3.9/site-packages/pipx/commands/ensure_path.py", line 7, in <module>\n    import userpath  # type: ignore\nModuleNotFoundError: No module named \'userpath\'\n'
2021-03-27 11:21:03,696 [ERROR]  <proc0> pipx: RunFailed
2021-03-27 11:22:57,195 [INFO]  <proc0> DeepLearning: Success
2021-03-27 11:27:36,474 [INFO]  <proc0> OneForAll: Success
2021-03-27 11:28:07,436 [ERROR]  Command 'None' in image 'sha256:63595fe45ec8664c4ae6eaff743050a234aabd9fd5f800b3b449ae028f64cfcd' returned non-zero exit status 1: b'Traceback (most recent call last):\n  File "//learn_math_fast/build_toc.py", line 67, in <module>\n    gen_toc(filename)\n  File "//learn_math_fast/build_toc.py", line 53, in gen_toc\n    md = _read_md(filename)\n  File "//learn_math_fast/build_toc.py", line 48, in _read_md\n    with open(filename, \'r\') as f:\nFileNotFoundError: [Errno 2] No such file or directory: \'README.md\'\n'
2021-03-27 11:28:07,436 [ERROR]  <proc0> learn_math_fast: Success
2021-03-27 11:31:32,032 [ERROR]  Command 'None' in image 'sha256:8ee0cfcad7cb4538ceb2c4f314e5d0493f557397116c5d08f1f634b032e817a3' returned non-zero exit status 1: b'Traceback (most recent call last):\n  File "test.py", line 1, in <module>\n    import akshare as ak\n  File "/akshare/akshare/__init__.py", line 1528, in <module>\n    from akshare.event.covid import (\n  File "/akshare/akshare/event/covid.py", line 15, in <module>\n    import jsonpath\nModuleNotFoundError: No module named \'jsonpath\'\n'
2021-03-27 11:31:32,033 [ERROR]  <proc0> akshare: RunFailed
2021-03-27 11:32:43,243 [ERROR]  Command 'None' in image 'sha256:8c2ee59bfe2d1fb596ffbffb65dd5a38a7e78b05b04531f91b82ec857e5b18f9' returned non-zero exit status 1: b'Traceback (most recent call last):\n  File "//Summer2021-Internships/sync.py", line 36, in <module>\n    html = parse_markdown_to_html_table()\n  File "//Summer2021-Internships/sync.py", line 9, in parse_markdown_to_html_table\n    readme = open("README.md", \'r\').read()\nFileNotFoundError: [Errno 2] No such file or directory: \'README.md\'\n'
2021-03-27 11:32:43,243 [ERROR]  <proc0> Summer2021-Internships: Success
2021-03-27 11:38:35,240 [ERROR]  <proc0> koalas: BuildFailed
2021-03-27 11:39:10,696 [ERROR]  Command 'None' in image 'sha256:b2d645b68e963ebf5677403dc9a43691af1abc2395116cedac442057f396a4c7' returned non-zero exit status 1: b'Traceback (most recent call last):\n  File "/usr/local/lib/python3.9/shutil.py", line 806, in move\n    os.rename(src, real_dst)\nFileNotFoundError: [Errno 2] No such file or directory: \'/root/.kb/data\' -> \'/root/.kb/default/data/data\'\n\nDuring handling of the above exception, another exception occurred:\n\nTraceback (most recent call last):\n  File "/usr/local/bin/kb", line 8, in <module>\n    sys.exit(main())\n  File "/usr/local/lib/python3.9/site-packages/kb/main.py", line 66, in main\n    dispatch(cmd, cmd_params, config=DEFAULT_CONFIG)\n  File "/usr/local/lib/python3.9/site-packages/kb/main.py", line 58, in dispatch\n    return COMMANDS[function](*args, **kwargs)\n  File "/usr/local/lib/python3.9/site-packages/kb/commands/search.py", line 41, in search\n    result = search_kb(args, config)\n  File "/usr/local/lib/python3.9/site-packages/kb/actions/search.py", line 40, in search_kb\n    initializer.init(config)\n  File "/usr/local/lib/python3.9/site-packages/kb/initializer.py", line 59, in init\n    fs.migrate_file_structure_015_to_016(config,conf)\n  File "/usr/local/lib/python3.9/site-packages/kb/filesystem.py", line 447, in migrate_file_structure_015_to_016\n    move_file(str(Path(kb_path_base,\'data\')),str(Path(kb_path_base,DEFAULT_KNOWLEDGEBASE,\'data\')))\n  File "/usr/local/lib/python3.9/site-packages/kb/filesystem.py", line 237, in move_file\n    shutil.move(source, dest)\n  File "/usr/local/lib/python3.9/shutil.py", line 820, in move\n    copy_function(src, real_dst)\n  File "/usr/local/lib/python3.9/shutil.py", line 435, in copy2\n    copyfile(src, dst, follow_symlinks=follow_symlinks)\n  File "/usr/local/lib/python3.9/shutil.py", line 264, in copyfile\n    with open(src, \'rb\') as fsrc, open(dst, \'wb\') as fdst:\nFileNotFoundError: [Errno 2] No such file or directory: \'/root/.kb/data\'\n'
2021-03-27 11:39:10,697 [ERROR]  <proc0> kb: Success
2021-03-27 11:59:14,057 [INFO]  <proc0> ResNeSt: Success
2021-03-27 12:01:16,614 [INFO]  <proc0> ECommerceCrawlers-TouTiao: Success
2021-03-27 12:02:58,067 [INFO]  <proc0> ECommerceCrawlers-East_money: Success
2021-03-27 12:08:48,593 [INFO]  <proc0> RAdam: Success
2021-03-27 12:09:31,778 [INFO]  <proc0> newscatcher: Success
2021-03-27 12:10:13,162 [ERROR]  Command 'None' in image 'sha256:2e164e71ed657a0e6e7d591c3c7645087f922f24e897b45bf07153fdde7fbe45' returned non-zero exit status 1: b'Traceback (most recent call last):\n  File "/GitHub520/fetch_ips.py", line 16, in <module>\n    from retry import retry\nModuleNotFoundError: No module named \'retry\'\n'
2021-03-27 12:10:13,163 [ERROR]  <proc0> GitHub520: RunFailed
2021-03-27 12:15:51,544 [INFO]  <proc0> vit-pytorch: Success
2021-03-27 12:21:05,907 [ERROR]  Command 'None' in image 'sha256:516329e631af1d0141f9ed73af5e9b476fa15a58a86666e1cf95a896457bada3' returned non-zero exit status 1: b'Traceback (most recent call last):\n  File "/VideoPose3D/run.py", line 41, in <module>\n    dataset = Human36mDataset(dataset_path)\n  File "/VideoPose3D/common/h36m_dataset.py", line 234, in __init__\n    data = np.load(path, allow_pickle=True)[\'positions_3d\'].item()\n  File "/usr/local/lib/python3.9/site-packages/numpy/lib/npyio.py", line 416, in load\n    fid = stack.enter_context(open(os_fspath(file), "rb"))\nFileNotFoundError: [Errno 2] No such file or directory: \'data/data_3d_h36m.npz\'\n'
2021-03-27 12:21:05,908 [ERROR]  <proc0> VideoPose3D: Success
2021-03-27 12:21:45,609 [INFO]  <proc0> real-url: Success
2021-03-27 12:21:51,370 [ERROR]  <proc0> clearml: GenerateFailed
2021-03-27 12:22:53,706 [ERROR]  <proc0> captum: GenerateFailed
2021-03-27 12:29:08,504 [ERROR]  <proc0> UGATIT-pytorch: BuildFailed
2021-03-27 12:29:34,119 [INFO]  <proc0> arxiv-latex-cleaner: Success
2021-03-27 12:30:20,149 [INFO]  <proc0> GeneralNewsExtractor: Success
2021-03-27 12:30:59,540 [ERROR]  Command 'None' in image 'sha256:af27e2bcfbd14a6bc7da65a91d26f067ec6ca319d1f19d140561a061b5e1b081' returned non-zero exit status 1: b'Traceback (most recent call last):\n  File "/DXY-COVID-19-Crawler/main.py", line 12, in <module>\n    crawler.run()\n  File "/DXY-COVID-19-Crawler/service/crawler.py", line 31, in run\n    self.crawler()\n  File "/DXY-COVID-19-Crawler/service/crawler.py", line 46, in crawler\n    soup = BeautifulSoup(r.content, \'lxml\')\n  File "/usr/local/lib/python3.9/site-packages/bs4/__init__.py", line 243, in __init__\n    raise FeatureNotFound(\nbs4.FeatureNotFound: Couldn\'t find a tree builder with the features you requested: lxml. Do you need to install a parser library?\n'
2021-03-27 12:30:59,540 [ERROR]  <proc0> DXY-COVID-19-Crawler: ImportError
2021-03-27 12:42:51,688 [ERROR]  Command 'None' in image 'sha256:c3edb22798841e57c1ca864ade19d37919e2f1dcb6b7197ad30662c84b194571' returned non-zero exit status 1: b'/facenet-pytorch/facenet_pytorch/models/utils/detect_face.py:250: SyntaxWarning: "is" with a literal. Did you mean "=="?\n  if method is "Min":\n\r  0%|          | 0.00/107M [00:00<?, ?B/s]\r  0%|          | 288k/107M [00:00<00:38, 2.92MB/s]\r  1%|          | 1.09M/107M [00:00<00:30, 3.63MB/s]\r  2%|\xe2\x96\x8f         | 1.97M/107M [00:00<00:24, 4.42MB/s]\r  3%|\xe2\x96\x8e         | 2.88M/107M [00:00<00:20, 5.25MB/s]\r  4%|\xe2\x96\x8e         | 3.80M/107M [00:00<00:17, 6.05MB/s]\r  4%|\xe2\x96\x8d         | 4.73M/107M [00:00<00:15, 6.82MB/s]\r  5%|\xe2\x96\x8c         | 5.64M/107M [00:00<00:14, 7.43MB/s]\r  6%|\xe2\x96\x8c         | 6.58M/107M [00:00<00:13, 8.02MB/s]\r  7%|\xe2\x96\x8b         | 7.48M/107M [00:00<00:12, 8.40MB/s]\r  8%|\xe2\x96\x8a         | 8.42M/107M [00:01<00:11, 8.77MB/s]\r  9%|\xe2\x96\x89         | 9.36M/107M [00:01<00:11, 9.07MB/s]\r 10%|\xe2\x96\x89         | 10.3M/107M [00:01<00:10, 9.24MB/s]\r 10%|\xe2\x96\x88         | 11.2M/107M [00:01<00:10, 9.34MB/s]\r 11%|\xe2\x96\x88\xe2\x96\x8f        | 12.2M/107M [00:01<00:10, 9.59MB/s]\r 12%|\xe2\x96\x88\xe2\x96\x8f        | 13.1M/107M [00:01<00:10, 9.60MB/s]\r 13%|\xe2\x96\x88\xe2\x96\x8e        | 14.1M/107M [00:01<00:10, 9.71MB/s]\r 14%|\xe2\x96\x88\xe2\x96\x8d        | 15.1M/107M [00:01<00:09, 9.85MB/s]\r 15%|\xe2\x96\x88\xe2\x96\x8c        | 16.1M/107M [00:01<00:09, 9.95MB/s]\r 16%|\xe2\x96\x88\xe2\x96\x8c        | 17.0M/107M [00:01<00:09, 9.98MB/s]\r 17%|\xe2\x96\x88\xe2\x96\x8b        | 18.0M/107M [00:02<00:09, 10.1MB/s]\r 18%|\xe2\x96\x88\xe2\x96\x8a        | 19.0M/107M [00:02<00:09, 10.2MB/s]\r 19%|\xe2\x96\x88\xe2\x96\x89        | 20.0M/107M [00:02<00:08, 10.2MB/s]\r 20%|\xe2\x96\x88\xe2\x96\x89        | 21.0M/107M [00:02<00:08, 10.2MB/s]\r 21%|\xe2\x96\x88\xe2\x96\x88        | 22.0M/107M [00:02<00:08, 10.3MB/s]\r 22%|\xe2\x96\x88\xe2\x96\x88\xe2\x96\x8f       | 23.1M/107M [00:02<00:08, 10.4MB/s]\r 23%|\xe2\x96\x88\xe2\x96\x88\xe2\x96\x8e       | 24.1M/107M [00:02<00:08, 10.4MB/s]\r 24%|\xe2\x96\x88\xe2\x96\x88\xe2\x96\x8e       | 25.1M/107M [00:02<00:08, 10.5MB/s]\r 24%|\xe2\x96\x88\xe2\x96\x88\xe2\x96\x8d       | 26.1M/107M [00:02<00:08, 10.5MB/s]\r 25%|\xe2\x96\x88\xe2\x96\x88\xe2\x96\x8c       | 27.2M/107M [00:02<00:07, 10.6MB/s]\r 26%|\xe2\x96\x88\xe2\x96\x88\xe2\x96\x8b       | 28.2M/107M [00:03<00:07, 10.6MB/s]\r 27%|\xe2\x96\x88\xe2\x96\x88\xe2\x96\x8b       | 29.2M/107M [00:03<00:07, 10.7MB/s]\r 28%|\xe2\x96\x88\xe2\x96\x88\xe2\x96\x8a       | 30.3M/107M [00:03<00:07, 10.6MB/s]\r 29%|\xe2\x96\x88\xe2\x96\x88\xe2\x96\x89       | 31.3M/107M [00:03<00:07, 10.6MB/s]\r 30%|\xe2\x96\x88\xe2\x96\x88\xe2\x96\x88       | 32.3M/107M [00:03<00:07, 10.3MB/s]\r 31%|\xe2\x96\x88\xe2\x96\x88\xe2\x96\x88\xe2\x96\x8f      | 33.4M/107M [00:03<00:07, 10.6MB/s]\r 32%|\xe2\x96\x88\xe2\x96\x88\xe2\x96\x88\xe2\x96\x8f      | 34.4M/107M [00:03<00:07, 10.7MB/s]\r 33%|\xe2\x96\x88\xe2\x96\x88\xe2\x96\x88\xe2\x96\x8e      | 35.5M/107M [00:03<00:06, 10.7MB/s]\r 34%|\xe2\x96\x88\xe2\x96\x88\xe2\x96\x88\xe2\x96\x8d      | 36.5M/107M [00:03<00:06, 10.5MB/s]\r 35%|\xe2\x96\x88\xe2\x96\x88\xe2\x96\x88\xe2\x96\x8c      | 37.6M/107M [00:03<00:06, 10.7MB/s]\r 36%|\xe2\x96\x88\xe2\x96\x88\xe2\x96\x88\xe2\x96\x8b      | 38.7M/107M [00:04<00:06, 10.8MB/s]\r 37%|\xe2\x96\x88\xe2\x96\x88\xe2\x96\x88\xe2\x96\x8b      | 39.8M/107M [00:04<00:06, 11.0MB/s]\r 38%|\xe2\x96\x88\xe2\x96\x88\xe2\x96\x88\xe2\x96\x8a      | 40.9M/107M [00:04<00:06, 11.1MB/s]\r 39%|\xe2\x96\x88\xe2\x96\x88\xe2\x96\x88\xe2\x96\x89      | 41.9M/107M [00:04<00:06, 11.0MB/s]\r 40%|\xe2\x96\x88\xe2\x96\x88\xe2\x96\x88\xe2\x96\x88      | 43.0M/107M [00:04<00:06, 11.0MB/s]\r 41%|\xe2\x96\x88\xe2\x96\x88\xe2\x96\x88\xe2\x96\x88\xe2\x96\x8f     | 44.2M/107M [00:04<00:05, 11.2MB/s]\r 42%|\xe2\x96\x88\xe2\x96\x88\xe2\x96\x88\xe2\x96\x88\xe2\x96\x8f     | 45.3M/107M [00:04<00:05, 11.3MB/s]\r 43%|\xe2\x96\x88\xe2\x96\x88\xe2\x96\x88\xe2\x96\x88\xe2\x96\x8e     | 46.4M/107M [00:04<00:05, 11.4MB/s]\r 45%|\xe2\x96\x88\xe2\x96\x88\xe2\x96\x88\xe2\x96\x88\xe2\x96\x8d     | 47.5M/107M [00:04<00:05, 11.6MB/s]\r 46%|\xe2\x96\x88\xe2\x96\x88\xe2\x96\x88\xe2\x96\x88\xe2\x96\x8c     | 48.6M/107M [00:04<00:05, 11.6MB/s]\r 47%|\xe2\x96\x88\xe2\x96\x88\xe2\x96\x88\xe2\x96\x88\xe2\x96\x8b     | 49.8M/107M [00:05<00:05, 11.7MB/s]\r 48%|\xe2\x96\x88\xe2\x96\x88\xe2\x96\x88\xe2\x96\x88\xe2\x96\x8a     | 50.9M/107M [00:05<00:05, 11.6MB/s]\r 49%|\xe2\x96\x88\xe2\x96\x88\xe2\x96\x88\xe2\x96\x88\xe2\x96\x8a     | 52.0M/107M [00:05<00:04, 11.5MB/s]\r 50%|\xe2\x96\x88\xe2\x96\x88\xe2\x96\x88\xe2\x96\x88\xe2\x96\x89     | 53.2M/107M [00:05<00:04, 11.7MB/s]\r 51%|\xe2\x96\x88\xe2\x96\x88\xe2\x96\x88\xe2\x96\x88\xe2\x96\x88     | 54.3M/107M [00:05<00:04, 11.7MB/s]\r 52%|\xe2\x96\x88\xe2\x96\x88\xe2\x96\x88\xe2\x96\x88\xe2\x96\x88\xe2\x96\x8f    | 55.5M/107M [00:05<00:04, 11.9MB/s]\r 53%|\xe2\x96\x88\xe2\x96\x88\xe2\x96\x88\xe2\x96\x88\xe2\x96\x88\xe2\x96\x8e    | 56.6M/107M [00:05<00:04, 11.8MB/s]\r 54%|\xe2\x96\x88\xe2\x96\x88\xe2\x96\x88\xe2\x96\x88\xe2\x96\x88\xe2\x96\x8d    | 57.8M/107M [00:05<00:04, 12.0MB/s]\r 55%|\xe2\x96\x88\xe2\x96\x88\xe2\x96\x88\xe2\x96\x88\xe2\x96\x88\xe2\x96\x8c    | 59.0M/107M [00:05<00:04, 11.9MB/s]\r 56%|\xe2\x96\x88\xe2\x96\x88\xe2\x96\x88\xe2\x96\x88\xe2\x96\x88\xe2\x96\x8b    | 60.1M/107M [00:05<00:04, 12.0MB/s]\r 57%|\xe2\x96\x88\xe2\x96\x88\xe2\x96\x88\xe2\x96\x88\xe2\x96\x88\xe2\x96\x8b    | 61.3M/107M [00:06<00:03, 12.1MB/s]\r 59%|\xe2\x96\x88\xe2\x96\x88\xe2\x96\x88\xe2\x96\x88\xe2\x96\x88\xe2\x96\x8a    | 62.5M/107M [00:06<00:03, 12.2MB/s]\r 60%|\xe2\x96\x88\xe2\x96\x88\xe2\x96\x88\xe2\x96\x88\xe2\x96\x88\xe2\x96\x89    | 63.7M/107M [00:06<00:03, 12.0MB/s]\r 61%|\xe2\x96\x88\xe2\x96\x88\xe2\x96\x88\xe2\x96\x88\xe2\x96\x88\xe2\x96\x88    | 64.9M/107M [00:06<00:03, 12.1MB/s]\r 62%|\xe2\x96\x88\xe2\x96\x88\xe2\x96\x88\xe2\x96\x88\xe2\x96\x88\xe2\x96\x88\xe2\x96\x8f   | 66.1M/107M [00:06<00:03, 12.3MB/s]\r 63%|\xe2\x96\x88\xe2\x96\x88\xe2\x96\x88\xe2\x96\x88\xe2\x96\x88\xe2\x96\x88\xe2\x96\x8e   | 67.4M/107M [00:06<00:03, 12.5MB/s]\r 64%|\xe2\x96\x88\xe2\x96\x88\xe2\x96\x88\xe2\x96\x88\xe2\x96\x88\xe2\x96\x88\xe2\x96\x8d   | 68.6M/107M [00:06<00:03, 12.6MB/s]\r 66%|\xe2\x96\x88\xe2\x96\x88\xe2\x96\x88\xe2\x96\x88\xe2\x96\x88\xe2\x96\x88\xe2\x96\x8c   | 69.9M/107M [00:06<00:02, 12.9MB/s]\r 67%|\xe2\x96\x88\xe2\x96\x88\xe2\x96\x88\xe2\x96\x88\xe2\x96\x88\xe2\x96\x88\xe2\x96\x8b   | 71.2M/107M [00:06<00:02, 13.2MB/s]\r 68%|\xe2\x96\x88\xe2\x96\x88\xe2\x96\x88\xe2\x96\x88\xe2\x96\x88\xe2\x96\x88\xe2\x96\x8a   | 72.6M/107M [00:07<00:02, 13.4MB/s]\r 69%|\xe2\x96\x88\xe2\x96\x88\xe2\x96\x88\xe2\x96\x88\xe2\x96\x88\xe2\x96\x88\xe2\x96\x89   | 73.9M/107M [00:07<00:02, 13.5MB/s]\r 71%|\xe2\x96\x88\xe2\x96\x88\xe2\x96\x88\xe2\x96\x88\xe2\x96\x88\xe2\x96\x88\xe2\x96\x88   | 75.2M/107M [00:07<00:02, 13.7MB/s]\r 72%|\xe2\x96\x88\xe2\x96\x88\xe2\x96\x88\xe2\x96\x88\xe2\x96\x88\xe2\x96\x88\xe2\x96\x88\xe2\x96\x8f  | 76.6M/107M [00:07<00:02, 13.9MB/s]\r 73%|\xe2\x96\x88\xe2\x96\x88\xe2\x96\x88\xe2\x96\x88\xe2\x96\x88\xe2\x96\x88\xe2\x96\x88\xe2\x96\x8e  | 78.0M/107M [00:07<00:02, 14.1MB/s]\r 75%|\xe2\x96\x88\xe2\x96\x88\xe2\x96\x88\xe2\x96\x88\xe2\x96\x88\xe2\x96\x88\xe2\x96\x88\xe2\x96\x8d  | 79.5M/107M [00:07<00:01, 14.5MB/s]\r 76%|\xe2\x96\x88\xe2\x96\x88\xe2\x96\x88\xe2\x96\x88\xe2\x96\x88\xe2\x96\x88\xe2\x96\x88\xe2\x96\x8c  | 80.9M/107M [00:07<00:01, 14.5MB/s]\r 77%|\xe2\x96\x88\xe2\x96\x88\xe2\x96\x88\xe2\x96\x88\xe2\x96\x88\xe2\x96\x88\xe2\x96\x88\xe2\x96\x8b  | 82.3M/107M [00:07<00:01, 14.6MB/s]\r 79%|\xe2\x96\x88\xe2\x96\x88\xe2\x96\x88\xe2\x96\x88\xe2\x96\x88\xe2\x96\x88\xe2\x96\x88\xe2\x96\x8a  | 83.8M/107M [00:07<00:01, 14.8MB/s]\r 80%|\xe2\x96\x88\xe2\x96\x88\xe2\x96\x88\xe2\x96\x88\xe2\x96\x88\xe2\x96\x88\xe2\x96\x88\xe2\x96\x89  | 85.2M/107M [00:07<00:01, 14.8MB/s]\r 81%|\xe2\x96\x88\xe2\x96\x88\xe2\x96\x88\xe2\x96\x88\xe2\x96\x88\xe2\x96\x88\xe2\x96\x88\xe2\x96\x88\xe2\x96\x8f | 86.8M/107M [00:08<00:01, 15.3MB/s]\r 83%|\xe2\x96\x88\xe2\x96\x88\xe2\x96\x88\xe2\x96\x88\xe2\x96\x88\xe2\x96\x88\xe2\x96\x88\xe2\x96\x88\xe2\x96\x8e | 88.4M/107M [00:08<00:01, 15.6MB/s]\r 84%|\xe2\x96\x88\xe2\x96\x88\xe2\x96\x88\xe2\x96\x88\xe2\x96\x88\xe2\x96\x88\xe2\x96\x88\xe2\x96\x88\xe2\x96\x8d | 90.0M/107M [00:08<00:01, 16.0MB/s]\r 86%|\xe2\x96\x88\xe2\x96\x88\xe2\x96\x88\xe2\x96\x88\xe2\x96\x88\xe2\x96\x88\xe2\x96\x88\xe2\x96\x88\xe2\x96\x8c | 91.6M/107M [00:08<00:00, 16.3MB/s]\r 87%|\xe2\x96\x88\xe2\x96\x88\xe2\x96\x88\xe2\x96\x88\xe2\x96\x88\xe2\x96\x88\xe2\x96\x88\xe2\x96\x88\xe2\x96\x8b | 93.2M/107M [00:08<00:00, 16.5MB/s]\r 89%|\xe2\x96\x88\xe2\x96\x88\xe2\x96\x88\xe2\x96\x88\xe2\x96\x88\xe2\x96\x88\xe2\x96\x88\xe2\x96\x88\xe2\x96\x89 | 95.0M/107M [00:08<00:00, 16.9MB/s]\r 91%|\xe2\x96\x88\xe2\x96\x88\xe2\x96\x88\xe2\x96\x88\xe2\x96\x88\xe2\x96\x88\xe2\x96\x88\xe2\x96\x88\xe2\x96\x88 | 96.7M/107M [00:08<00:00, 17.3MB/s]\r 92%|\xe2\x96\x88\xe2\x96\x88\xe2\x96\x88\xe2\x96\x88\xe2\x96\x88\xe2\x96\x88\xe2\x96\x88\xe2\x96\x88\xe2\x96\x88\xe2\x96\x8f| 98.4M/107M [00:08<00:00, 17.6MB/s]\r 94%|\xe2\x96\x88\xe2\x96\x88\xe2\x96\x88\xe2\x96\x88\xe2\x96\x88\xe2\x96\x88\xe2\x96\x88\xe2\x96\x88\xe2\x96\x88\xe2\x96\x8d| 100M/107M [00:08<00:00, 17.8MB/s] \r 96%|\xe2\x96\x88\xe2\x96\x88\xe2\x96\x88\xe2\x96\x88\xe2\x96\x88\xe2\x96\x88\xe2\x96\x88\xe2\x96\x88\xe2\x96\x88\xe2\x96\x8c| 102M/107M [00:08<00:00, 18.2MB/s]\r 97%|\xe2\x96\x88\xe2\x96\x88\xe2\x96\x88\xe2\x96\x88\xe2\x96\x88\xe2\x96\x88\xe2\x96\x88\xe2\x96\x88\xe2\x96\x88\xe2\x96\x8b| 104M/107M [00:09<00:00, 18.6MB/s]\r 99%|\xe2\x96\x88\xe2\x96\x88\xe2\x96\x88\xe2\x96\x88\xe2\x96\x88\xe2\x96\x88\xe2\x96\x88\xe2\x96\x88\xe2\x96\x88\xe2\x96\x89| 106M/107M [00:09<00:00, 18.9MB/s]\r100%|\xe2\x96\x88\xe2\x96\x88\xe2\x96\x88\xe2\x96\x88\xe2\x96\x88\xe2\x96\x88\xe2\x96\x88\xe2\x96\x88\xe2\x96\x88\xe2\x96\x88| 107M/107M [00:09<00:00, 12.2MB/s]\nTraceback (most recent call last):\n  File "test.py", line 9, in <module>\n    img_embedding = resnet(img_cropped.unsqueeze(0))\nNameError: name \'img_cropped\' is not defined\n'
2021-03-27 12:42:51,689 [ERROR]  <proc0> facenet-pytorch: Success
2021-03-27 12:43:07,990 [ERROR]  Command 'None' in image 'sha256:027adae19dc0fece00637ec2eb898a51e7dd0beaf9954497096c170846c91cdb' returned non-zero exit status 1: b"\n*******************************************************************************\n/PrettyErrors/test.py\n19 <module>\n    exception_file_color=pretty_errors.BRIGHT_BLUE\n)\nirrelevant = pretty_errors.config.copy()\nirrelevant.line_color = irrelevant.code_color = irrelevant.filename_color = irrelevant.function_color = irrelevant.line_number_color = (\n    pretty_errors.GREY\n)\npretty_errors.pathed_config(irrelevant, 'c:/python', 'c:/users')\n\n\nimport os\nos.rename('nofile', 'stillnofile')\n\nFileNotFoundError:\n2\nNo such file or directory\nnofile\nstillnofile\n"
2021-03-27 12:43:07,991 [ERROR]  <proc0> PrettyErrors: Success
2021-03-27 12:44:13,231 [INFO]  <proc0> m2cgen: Success
2021-03-27 12:46:30,141 [INFO]  <proc0> dirmap: Success
2021-03-27 12:46:41,826 [INFO]  <proc0> latexify_py: Success
2021-03-27 12:47:49,827 [ERROR]  Command 'None' in image 'sha256:caa7098b800dd720d123aad17ec08ea88047ddfeee0f6e51310cc21d014432c5' returned non-zero exit status 1: b'Traceback (most recent call last):\n  File "/springer_free_books/main.py", line 48, in <module>\n    books = pd.read_excel(table_url)\n  File "/usr/local/lib/python3.9/site-packages/pandas/util/_decorators.py", line 296, in wrapper\n    return func(*args, **kwargs)\n  File "/usr/local/lib/python3.9/site-packages/pandas/io/excel/_base.py", line 304, in read_excel\n    io = ExcelFile(io, engine=engine)\n  File "/usr/local/lib/python3.9/site-packages/pandas/io/excel/_base.py", line 867, in __init__\n    self._reader = self._engines[engine](self._io)\n  File "/usr/local/lib/python3.9/site-packages/pandas/io/excel/_xlrd.py", line 21, in __init__\n    import_optional_dependency("xlrd", extra=err_msg)\n  File "/usr/local/lib/python3.9/site-packages/pandas/compat/_optional.py", line 110, in import_optional_dependency\n    raise ImportError(msg) from None\nImportError: Missing optional dependency \'xlrd\'. Install xlrd >= 1.0.0 for Excel support Use pip or conda to install xlrd.\n'
2021-03-27 12:47:49,828 [ERROR]  <proc0> springer_free_books: RunFailed
2021-03-27 12:49:36,749 [ERROR]  Command 'None' in image 'sha256:1f75d8923c3ae77f21b365259bdc6a9c70fa9008986a14c309ca5a7239d1d0e0' returned non-zero exit status 1: b'Traceback (most recent call last):\n  File "/stumpy/test.py", line 1, in <module>\n    import stumpy\n  File "/stumpy/stumpy/__init__.py", line 3, in <module>\n    from .stump import stump  # noqa: F401\n  File "/stumpy/stumpy/stump.py", line 8, in <module>\n    from numba import njit, prange, config\n  File "/usr/local/lib/python3.9/site-packages/numba/__init__.py", line 25, in <module>\n    from .decorators import autojit, cfunc, generated_jit, jit, njit, stencil\n  File "/usr/local/lib/python3.9/site-packages/numba/decorators.py", line 12, in <module>\n    from .targets import registry\n  File "/usr/local/lib/python3.9/site-packages/numba/targets/registry.py", line 5, in <module>\n    from . import cpu\n  File "/usr/local/lib/python3.9/site-packages/numba/targets/cpu.py", line 9, in <module>\n    from numba import _dynfunc, config\nImportError: /usr/local/lib/python3.9/site-packages/numba/_dynfunc.cpython-39-x86_64-linux-gnu.so: undefined symbol: _PyObject_GC_UNTRACK\n'
2021-03-27 12:49:36,750 [ERROR]  <proc0> stumpy: RunFailed
2021-03-27 12:57:46,827 [INFO]  <proc0> SegLoss: Success
2021-03-27 12:57:56,756 [INFO]  <proc0> coding-problems: Success
2021-03-27 12:58:10,803 [INFO]  <proc0> dongbei: Success
2021-03-27 12:59:00,788 [INFO]  <proc0> returns: Success
2021-03-27 12:59:25,284 [INFO]  <proc0> xxh: Success
2021-03-27 13:00:19,020 [ERROR]  Command 'None' in image 'sha256:861ebdf06ad6d658493ccdb995c9b7879409177975606cdf957d8a6c0fbbe690' returned non-zero exit status 1: b'Traceback (most recent call last):\n  File "/usr/local/lib/python3.9/site-packages/apistar/cli.py", line 84, in _load_config\n    config = apistar.validate(content, format="config", encoding="yaml")\n  File "/usr/local/lib/python3.9/site-packages/apistar/core.py", line 54, in validate\n    token = tokenize(schema)\n  File "/usr/local/lib/python3.9/site-packages/typesystem/tokenize/tokenize_yaml.py", line 26, in tokenize_yaml\n    assert yaml is not None, "\'pyyaml\' must be installed."\nAssertionError: \'pyyaml\' must be installed.\n\nDuring handling of the above exception, another exception occurred:\n\nTraceback (most recent call last):\n  File "/usr/local/bin/apistar", line 8, in <module>\n    sys.exit(cli())\n  File "/usr/local/lib/python3.9/site-packages/click/core.py", line 829, in __call__\n    return self.main(*args, **kwargs)\n  File "/usr/local/lib/python3.9/site-packages/click/core.py", line 782, in main\n    rv = self.invoke(ctx)\n  File "/usr/local/lib/python3.9/site-packages/click/core.py", line 1259, in invoke\n    return _process_result(sub_ctx.command.invoke(sub_ctx))\n  File "/usr/local/lib/python3.9/site-packages/click/core.py", line 1066, in invoke\n    return ctx.invoke(self.callback, **ctx.params)\n  File "/usr/local/lib/python3.9/site-packages/click/core.py", line 610, in invoke\n    return callback(*args, **kwargs)\n  File "/usr/local/lib/python3.9/site-packages/apistar/cli.py", line 127, in validate\n    config = _load_config(options, verbose=verbose)\n  File "/usr/local/lib/python3.9/site-packages/apistar/cli.py", line 85, in _load_config\n    except (ParseError, ValidationError) as exc:\nNameError: name \'ParseError\' is not defined\n'
2021-03-27 13:00:19,020 [ERROR]  <proc0> apistar: Success
2021-03-27 13:02:57,824 [INFO]  <proc0> pandarallel: Success
2021-03-27 13:04:30,037 [INFO]  <proc0> DecryptLogin: Success
2021-03-27 13:04:30,985 [ERROR]  <proc0> webpy: GenerateFailed
2021-03-27 13:05:51,911 [INFO]  <proc0> SSRFmap: Success
2021-03-27 13:05:52,761 [ERROR]  <proc0> python-for-absolute-beginners-course: GenerateFailed
2021-03-27 13:15:30,991 [INFO]  <proc0> lambda-networks: Success
2021-03-27 13:20:22,921 [ERROR]  <proc0> dimensionality_reduction_alo_codes: BuildFailed
2021-03-27 13:34:29,789 [INFO]  <proc0> pytorch-openai-transformer-lm: Success
2021-03-27 13:40:33,016 [INFO]  <proc0> finetune-transformer-lm: Success
2021-03-27 13:40:50,104 [INFO]  <proc0> data-science-blogs: Success
2021-03-27 13:40:51,685 [ERROR]  <proc0> SSRSpeed: GenerateFailed
2021-03-27 13:40:55,325 [ERROR]  <proc0> dirsearch: GenerateFailed
2021-03-27 13:42:13,502 [ERROR]  Command 'None' in image 'sha256:43af4640693ed38fe4bdfb54d76dc9c1ed96a06989f76b7ad77826a9053121f9' returned non-zero exit status 1: b'Traceback (most recent call last):\n  File "/usr/local/lib/python3.9/site-packages/impacket/dcerpc/v5/transport.py", line 346, in connect\n    self.__socket.connect(sa)\nsocket.timeout: timed out\n\nDuring handling of the above exception, another exception occurred:\n\nTraceback (most recent call last):\n  File "/CVE-2020-1472/./zerologon_tester.py", line 86, in <module>\n    perform_attack(\'\\\\\\\\\' + dc_name, dc_ip, dc_name)\n  File "/CVE-2020-1472/./zerologon_tester.py", line 62, in perform_attack\n    rpc_con = try_zero_authenticate(dc_handle, dc_ip, target_computer)\n  File "/CVE-2020-1472/./zerologon_tester.py", line 22, in try_zero_authenticate\n    binding = epm.hept_map(dc_ip, nrpc.MSRPC_UUID_NRPC, protocol=\'ncacn_ip_tcp\')\n  File "/usr/local/lib/python3.9/site-packages/impacket/dcerpc/v5/epm.py", line 1256, in hept_map\n    dce.connect()\n  File "/usr/local/lib/python3.9/site-packages/impacket/dcerpc/v5/rpcrt.py", line 801, in connect\n    return self._transport.connect()\n  File "/usr/local/lib/python3.9/site-packages/impacket/dcerpc/v5/transport.py", line 349, in connect\n    raise DCERPCException("Could not connect: %s" % msg)\nimpacket.dcerpc.v5.rpcrt.DCERPCException: Could not connect: timed out\n'
2021-03-27 13:42:13,502 [ERROR]  <proc0> CVE-2020-1472: Success
2021-03-27 13:43:47,881 [INFO]  <proc0> 30-Days-Of-Python: Success
2021-03-27 13:48:29,082 [INFO]  <proc0> Vxscan: Success
2021-03-27 13:49:36,684 [INFO]  <proc0> mnssp3-DNA: Success
2021-03-27 13:55:31,735 [ERROR]  Command 'None' in image 'sha256:4a9ddb978ffccb308ea8732c2f3e0e01dbc459b9b775ef73715b38a204df5277' returned non-zero exit status 1: b'Traceback (most recent call last):\n  File "test.py", line 108, in <module>\n    dl_model(sys.argv).execute(name=sys.argv[1])\nIndexError: list index out of range\n'
2021-03-27 13:55:31,735 [ERROR]  <proc0> mnssp3-EMR: Success
2021-03-27 14:03:17,415 [ERROR]  Command 'None' in image 'sha256:ccff88c42962ec6d23603f1accf47972304f52e51a797fd5196890530b5b8fd2' returned non-zero exit status 1: b'Traceback (most recent call last):\n  File "/usr/local/lib/python3.9/site-packages/keras/__init__.py", line 3, in <module>\n    from tensorflow.keras.layers.experimental.preprocessing import RandomRotation\nModuleNotFoundError: No module named \'tensorflow\'\n\nDuring handling of the above exception, another exception occurred:\n\nTraceback (most recent call last):\n  File "/mnssp3-EEG/EEG/EpilepsyDetection/Python/EEG/predict.py", line 7, in <module>\n    from keras.models import Sequential \n  File "/usr/local/lib/python3.9/site-packages/keras/__init__.py", line 5, in <module>\n    raise ImportError(\nImportError: Keras requires TensorFlow 2.2 or higher. Install TensorFlow via `pip install tensorflow`\n'
2021-03-27 14:03:17,416 [ERROR]  <proc0> mnssp3-EEG: RunFailed
2021-03-27 14:10:02,148 [INFO]  <proc0> proxylessnas: Success
2021-03-27 14:12:40,863 [INFO]  <proc0> sweetviz: Success
2021-03-27 14:13:43,390 [INFO]  <proc0> policy_sentry: Success
2021-03-27 14:14:19,705 [ERROR]  Command 'None' in image 'sha256:bb43bcf5214bb357b1690f77c1b999af466608e72895bad17f849244f02c8269' returned non-zero exit status 2: b'usage: noisy.py [-h] [--log -l] --config -c [--timeout -t]\nnoisy.py: error: the following arguments are required: --config\n'
2021-03-27 14:14:19,705 [ERROR]  <proc0> noisy: Success
2021-03-27 14:22:24,168 [INFO]  <proc0> pytorch-meta: Success
2021-03-27 14:23:18,378 [INFO]  <proc0> links-uteis: Success
2021-03-27 14:23:55,169 [INFO]  <proc0> WeblogicScan: Success
2021-03-27 14:25:23,519 [INFO]  <proc0> heartrate: Success
2021-03-27 14:26:14,639 [ERROR]  Command 'None' in image 'sha256:c6bef0c16975460126511cbe46866a6892129b39c7f5b4af83d1ed41460d07ec' returned non-zero exit status 1: b'Traceback (most recent call last):\n  File "/gitGraber/gitGraber.py", line 358, in <module>\n    monitor()\n  File "/gitGraber/gitGraber.py", line 39, in monitor\n    my_cron = CronTab(user=True)\nTypeError: __init__() got an unexpected keyword argument \'user\'\n'
2021-03-27 14:26:14,639 [ERROR]  <proc0> gitGraber: Success
2021-03-27 14:35:24,760 [INFO]  <proc0> karateclub: Success
2021-03-27 14:37:18,010 [INFO]  <proc0> archivy: Success
2021-03-27 14:41:40,911 [ERROR]  Command 'None' in image 'sha256:6d7317efbcbc7c2da437d9186eaafb3e018c94e2f77deb0b74c0e9b35b395b31' returned non-zero exit status 1: b'2021-03-27 06:41:37.869478: W tensorflow/stream_executor/platform/default/dso_loader.cc:60] Could not load dynamic library \'libcudart.so.11.0\'; dlerror: libcudart.so.11.0: cannot open shared object file: No such file or directory\n2021-03-27 06:41:37.869524: I tensorflow/stream_executor/cuda/cudart_stub.cc:29] Ignore above cudart dlerror if you do not have a GPU set up on your machine.\nTraceback (most recent call last):\n  File "train.py", line 8, in <module>\n    from gcn.models import GCN, MLP\n  File "/gcn/gcn/models.py", line 1, in <module>\n    from gcn.layers import *\n  File "/gcn/gcn/layers.py", line 4, in <module>\n    flags = tf.app.flags\nAttributeError: module \'tensorflow\' has no attribute \'app\'\n'
2021-03-27 14:41:40,911 [ERROR]  <proc0> gcn: ImportError
2021-03-27 14:47:28,765 [ERROR]  Command 'None' in image 'sha256:c62c9eff0b9fc7a2eb5a83ef559d0124f25e931c494ea9887f5b1c576af86602' returned non-zero exit status 1: b'Traceback (most recent call last):\n  File "/leedeeprl-notes/codes/A2C/main.py", line 17, in <module>\n    from torch.utils.tensorboard import SummaryWriter\n  File "/usr/local/lib/python3.9/site-packages/torch/utils/tensorboard/__init__.py", line 1, in <module>\n    import tensorboard\nModuleNotFoundError: No module named \'tensorboard\'\n'
2021-03-27 14:47:28,765 [ERROR]  <proc0> leedeeprl-notes: RunFailed
2021-03-27 14:49:06,374 [INFO]  <proc0> django-vue-template: Success
2021-03-27 14:50:29,059 [INFO]  <proc0> GScan: Success
2021-03-27 14:51:07,891 [INFO]  <proc0> distribution-is-all-you-need: Success
2021-03-27 14:59:34,453 [INFO]  <proc0> flops-counter.pytorch: Success
2021-03-27 14:59:57,297 [ERROR]  Command 'None' in image 'sha256:c5fbb24f24dd1e7547f809d59410df8f3cb131bebe3a30268a30dcf2903f7de0' returned non-zero exit status 1: b'Warning: Output is not a terminal (fd=1).\nWarning: Input is not a terminal (fd=0).\nTraceback (most recent call last):\n  File "/usr/local/lib/python3.9/asyncio/selector_events.py", line 261, in _add_reader\n    key = self._selector.get_key(fd)\n  File "/usr/local/lib/python3.9/selectors.py", line 193, in get_key\n    raise KeyError("{!r} is not registered".format(fileobj)) from None\nKeyError: \'0 is not registered\'\n\nDuring handling of the above exception, another exception occurred:\n\nTraceback (most recent call last):\n  File "/PyInquirer/test.py", line 12, in <module>\n    answers = prompt.prompt(questions)\n  File "/PyInquirer/PyInquirer/prompt.py", line 71, in prompt\n    result = getattr(prompts, type_).question(message, **_kwargs)\n  File "/PyInquirer/PyInquirer/prompts/input.py", line 44, in question\n    return prompt(\n  File "/usr/local/lib/python3.9/site-packages/prompt_toolkit/shortcuts/prompt.py", line 1384, in prompt\n    return session.prompt(\n  File "/usr/local/lib/python3.9/site-packages/prompt_toolkit/shortcuts/prompt.py", line 1013, in prompt\n    return self.app.run(set_exception_handler=set_exception_handler)\n  File "/usr/local/lib/python3.9/site-packages/prompt_toolkit/application/application.py", line 816, in run\n    return loop.run_until_complete(\n  File "/usr/local/lib/python3.9/asyncio/base_events.py", line 642, in run_until_complete\n    return future.result()\n  File "/usr/local/lib/python3.9/site-packages/prompt_toolkit/application/application.py", line 783, in run_async\n    return await _run_async2()\n  File "/usr/local/lib/python3.9/site-packages/prompt_toolkit/application/application.py", line 765, in _run_async2\n    result = await _run_async()\n  File "/usr/local/lib/python3.9/site-packages/prompt_toolkit/application/application.py", line 696, in _run_async\n    with self.input.raw_mode(), self.input.attach(\n  File "/usr/local/lib/python3.9/contextlib.py", line 117, in __enter__\n    return next(self.gen)\n  File "/usr/local/lib/python3.9/site-packages/prompt_toolkit/input/vt100.py", line 171, in _attached_input\n    loop.add_reader(fd, callback_wrapper)\n  File "/usr/local/lib/python3.9/asyncio/selector_events.py", line 336, in add_reader\n    self._add_reader(fd, callback, *args)\n  File "/usr/local/lib/python3.9/asyncio/selector_events.py", line 263, in _add_reader\n    self._selector.register(fd, selectors.EVENT_READ,\n  File "/usr/local/lib/python3.9/selectors.py", line 360, in register\n    self._selector.register(key.fd, poller_events)\nPermissionError: [Errno 1] Operation not permitted\n'
2021-03-27 14:59:57,297 [ERROR]  <proc0> PyInquirer: Success
2021-03-27 15:03:41,453 [ERROR]  Command 'None' in image 'sha256:a948a1f49913298dd8ef5b95a01eead9287a2cb0b2dbf1fc79610c0a94dcadc4' returned non-zero exit status 1: b'2021-03-27 07:03:38.752925: W tensorflow/stream_executor/platform/default/dso_loader.cc:60] Could not load dynamic library \'libcudart.so.11.0\'; dlerror: libcudart.so.11.0: cannot open shared object file: No such file or directory\n2021-03-27 07:03:38.752966: I tensorflow/stream_executor/cuda/cudart_stub.cc:29] Ignore above cudart dlerror if you do not have a GPU set up on your machine.\nTraceback (most recent call last):\n  File "attention.py", line 4, in <module>\n    from blocksparse import BlocksparseTransformer\n  File "/usr/local/lib/python3.8/site-packages/blocksparse/__init__.py", line 3, in <module>\n    from blocksparse.utils import (\n  File "/usr/local/lib/python3.8/site-packages/blocksparse/utils.py", line 15, in <module>\n    data_files_path = tf.resource_loader.get_data_files_path()\nAttributeError: module \'tensorflow\' has no attribute \'resource_loader\'\n'
2021-03-27 15:03:41,454 [ERROR]  <proc0> sparse_attention: ImportError
2021-03-27 15:08:28,280 [INFO]  <proc0> micronet: Success
2021-03-27 15:15:48,583 [ERROR]  Command 'None' in image 'sha256:4a0362c6ec57660594c51a11aa6bfba1f863636ddae2c0edff6a5be43ed4d517' returned non-zero exit status 1: b'2021-03-30 12:37:06.702831: W tensorflow/stream_executor/platform/default/dso_loader.cc:60] Could not load dynamic library \'libcudart.so.11.0\'; dlerror: libcudart.so.11.0: cannot open shared object file: No such file or directory\n2021-03-30 12:37:06.702876: I tensorflow/stream_executor/cuda/cudart_stub.cc:29] Ignore above cudart dlerror if you do not have a GPU set up on your machine.\nTraceback (most recent call last):\n  File "/usr/local/lib/python3.8/site-packages/scipy/io/matlab/mio.py", line 39, in _open_file\n    return open(file_like, mode), True\nFileNotFoundError: [Errno 2] No such file or directory: \'../large_files/train_32x32.mat\'\n\nDuring handling of the above exception, another exception occurred:\n\nTraceback (most recent call last):\n  File "edge_benchmark.py", line 132, in <module>\n    main()\n  File "edge_benchmark.py", line 51, in main\n    train = loadmat(\'../large_files/train_32x32.mat\')\n  File "/usr/local/lib/python3.8/site-packages/scipy/io/matlab/mio.py", line 222, in loadmat\n    with _open_file_context(file_name, appendmat) as f:\n  File "/usr/local/lib/python3.8/contextlib.py", line 113, in __enter__\n    return next(self.gen)\n  File "/usr/local/lib/python3.8/site-packages/scipy/io/matlab/mio.py", line 17, in _open_file_context\n    f, opened = _open_file(file_like, appendmat, mode)\n  File "/usr/local/lib/python3.8/site-packages/scipy/io/matlab/mio.py", line 45, in _open_file\n    return open(file_like, mode), True\nFileNotFoundError: [Errno 2] No such file or directory: \'../large_files/train_32x32.mat\'\n'
2021-03-27 15:15:48,583 [ERROR]  <proc0> machine_learning_examples: Success
2021-03-27 15:16:37,024 [INFO]  <proc0> BlueKeep: Success
2021-03-27 15:17:35,877 [ERROR]  <proc0> wechat_friends: BuildFailed
2021-03-27 15:23:50,900 [ERROR]  <proc0> petastorm: BuildFailed
2021-03-27 15:26:31,156 [ERROR]  Command 'None' in image 'sha256:3467af62c0f85cfd1b2e623cc1dd28cd3aaa78571b58daee87bff9a868376776' returned non-zero exit status 1: b'Traceback (most recent call last):\n  File "/blackhat-python3/chapter04/pic_carver.py", line 2, in <module>\n    from kamene.all import *\nModuleNotFoundError: No module named \'kamene\'\n'
2021-03-27 15:26:31,157 [ERROR]  <proc0> blackhat-python3: RunFailed
2021-03-27 15:34:03,148 [ERROR]  Command 'None' in image 'sha256:d65dbe2a08510703acb2163fad0059529e8375a2914cdc073e086edc9c23fdff' returned non-zero exit status 1: b'Traceback (most recent call last):\n  File "/neural_prophet/test.py", line 1, in <module>\n    from neuralprophet import NeuralProphet\n  File "/neural_prophet/neuralprophet/__init__.py", line 24, in <module>\n    from .forecaster import NeuralProphet\n  File "/neural_prophet/neuralprophet/forecaster.py", line 11, in <module>\n    from torch_lr_finder import LRFinder\nModuleNotFoundError: No module named \'torch_lr_finder\'\n'
2021-03-27 15:34:03,148 [ERROR]  <proc0> neural_prophet: RunFailed
2021-03-27 15:34:33,275 [INFO]  <proc0> pyp: Success
2021-03-27 15:40:42,920 [INFO]  <proc0> SimpleHTR: Success
2021-03-27 15:47:45,481 [INFO]  <proc0> SuperGluePretrainedNetwork: Success
2021-03-27 15:54:45,619 [INFO]  <proc0> SuperPointPretrainedNetwork: Success
2021-03-27 15:56:32,851 [ERROR]  <proc0> pydub: BuildFailed
2021-03-27 16:02:03,483 [INFO]  <proc0> efficientnet: Success
2021-03-27 16:07:33,327 [ERROR]  Command 'None' in image 'sha256:2f7045bf2a28633f38d7aac1bb1dc3821c05d1f8d565fce9c0a600114d776772' returned non-zero exit status 1: b'2021-03-27 08:07:30.004824: W tensorflow/stream_executor/platform/default/dso_loader.cc:60] Could not load dynamic library \'libcudart.so.11.0\'; dlerror: libcudart.so.11.0: cannot open shared object file: No such file or directory\n2021-03-27 08:07:30.004872: I tensorflow/stream_executor/cuda/cudart_stub.cc:29] Ignore above cudart dlerror if you do not have a GPU set up on your machine.\nTraceback (most recent call last):\n  File "image_demo.py", line 33, in <module>\n    return_tensors = utils.read_pb_return_tensors(graph, pb_file, return_elements)\n  File "/tensorflow-yolov3/core/utils.py", line 122, in read_pb_return_tensors\n    with tf.gfile.FastGFile(pb_file, \'rb\') as f:\nAttributeError: module \'tensorflow\' has no attribute \'gfile\'\n'
2021-03-27 16:07:33,328 [ERROR]  <proc0> tensorflow-yolov3: ImportError
2021-03-27 16:11:43,711 [ERROR]  Command 'None' in image 'sha256:94d4b546e38f12c273819379e96b52bb88673503891e00b18ba21e9ba2de6477' returned non-zero exit status 1: b'2021-03-27 08:11:40.576255: W tensorflow/stream_executor/platform/default/dso_loader.cc:60] Could not load dynamic library \'libcudart.so.11.0\'; dlerror: libcudart.so.11.0: cannot open shared object file: No such file or directory\n2021-03-27 08:11:40.576298: I tensorflow/stream_executor/cuda/cudart_stub.cc:29] Ignore above cudart dlerror if you do not have a GPU set up on your machine.\nTraceback (most recent call last):\n  File "/usr/local/bin/bert-base-serving-start", line 8, in <module>\n    sys.exit(start_server())\n  File "/usr/local/lib/python3.8/site-packages/bert_base/runs/__init__.py", line 12, in start_server\n    from bert_base.server import BertServer\n  File "/usr/local/lib/python3.8/site-packages/bert_base/server/__init__.py", line 38, in <module>\n    from bert_base.train.models import convert_id_to_label\n  File "/usr/local/lib/python3.8/site-packages/bert_base/train/models.py", line 10, in <module>\n    from bert_base.train.lstm_crf_layer import BLSTM_CRF\n  File "/usr/local/lib/python3.8/site-packages/bert_base/train/lstm_crf_layer.py", line 9, in <module>\n    from tensorflow.contrib import rnn\nModuleNotFoundError: No module named \'tensorflow.contrib\'\n'
2021-03-27 16:11:43,712 [ERROR]  <proc0> BERT-BiLSTM-CRF-NER: RunFailed
2021-03-27 16:11:49,883 [ERROR]  <proc0> mars: GenerateFailed
2021-03-27 16:15:57,474 [ERROR]  <proc0> jina: BuildFailed
2021-03-27 16:16:41,888 [INFO]  <proc0> starlette: Success
2021-03-27 16:16:41,891 [INFO]  71/100, 0.71
2021-03-27 16:16:41,891 [INFO]  ----------END----------

