2021-08-18 22:36:11,984 [INFO]  ----------START----------
2021-08-18 22:42:27,680 [INFO]  <proc0> tiler: Success
2021-08-18 22:44:20,829 [INFO]  <proc0> metaflow: Success
2021-08-18 22:48:21,473 [ERROR]  Command 'None' in image 'sha256:44ae4abcb8895e8249704d8dfa6b13411ff80e5474ad32a1380acca9a3c3c306' returned non-zero exit status 1: b'Traceback (most recent call last):\n  File "test.py", line 1, in <module>\n    from tinygrad.tensor import Tensor\n  File "/tinygrad/tinygrad/__init__.py", line 1, in <module>\n    import tinygrad.optim\n  File "/tinygrad/tinygrad/optim.py", line 2, in <module>\n    from tinygrad.tensor import Tensor\n  File "/tinygrad/tinygrad/tensor.py", line 17\n    print(f"{name:>20} : {debug_counts[name]:>6} {debug_times[name]:>10.2f} ms")\n                                                                              ^\nSyntaxError: invalid syntax\n'
2021-08-18 22:48:21,473 [ERROR]  <proc0> tinygrad: RunFailed
2021-08-18 22:48:27,106 [ERROR]  <proc0> sktime: GenerateFailed
2021-08-18 22:49:03,016 [INFO]  <proc0> scalene: Success
2021-08-18 22:50:37,281 [INFO]  <proc0> Python-crawler-tutorial-starts-from-zero: Success
2021-08-18 22:51:08,234 [INFO]  <proc0> jd-assistant: Success
2021-08-18 22:51:49,166 [INFO]  <proc0> autoscraper: Inconsistent
2021-08-18 22:52:02,062 [INFO]  <proc0> bullet: Success
2021-08-18 22:52:32,448 [ERROR]  Command 'None' in image 'sha256:e22c2a0dfee5dac2689b23dc81cf469455eb4b2922ac75a10bcafb9b5f5e6de4' returned non-zero exit status 1: b'Traceback (most recent call last):\n  File "/usr/local/bin/pipx", line 5, in <module>\n    from pipx.main import cli\n  File "/usr/local/lib/python3.9/site-packages/pipx/main.py", line 21, in <module>\n    from pipx import commands, constants\n  File "/usr/local/lib/python3.9/site-packages/pipx/commands/__init__.py", line 1, in <module>\n    from pipx.commands.ensure_path import ensure_pipx_paths\n  File "/usr/local/lib/python3.9/site-packages/pipx/commands/ensure_path.py", line 7, in <module>\n    import userpath  # type: ignore\nModuleNotFoundError: No module named \'userpath\'\n'
2021-08-18 22:52:32,448 [ERROR]  <proc0> pipx: RunFailed
2021-08-18 22:53:31,697 [INFO]  <proc0> chinese_province_city_area_mapper: Success
2021-08-18 22:58:17,078 [INFO]  <proc0> OneForAll: Success
2021-08-18 22:58:28,911 [INFO]  <proc0> learn_math_fast: Success
2021-08-18 23:02:54,110 [ERROR]  Command 'None' in image 'sha256:a7e0fcfa34c4e7f1986606ea25e6a26b47195a8982ca9d1a43522d901b697eb6' returned non-zero exit status 1: b'Traceback (most recent call last):\n  File "test.py", line 1, in <module>\n    import akshare as ak\n  File "/akshare/akshare/__init__.py", line 1528, in <module>\n    from akshare.event.covid import (\n  File "/akshare/akshare/event/covid.py", line 15, in <module>\n    import jsonpath\nModuleNotFoundError: No module named \'jsonpath\'\n'
2021-08-18 23:02:54,110 [ERROR]  <proc0> akshare: RunFailed
2021-08-18 23:06:48,623 [INFO]  <proc0> ASCII-generator: Success
2021-08-18 23:09:00,440 [INFO]  <proc0> pyts: Success
2021-08-18 23:09:03,603 [ERROR]  <proc0> SimCSE: GenerateFailed
2021-08-18 23:18:39,225 [INFO]  <proc0> ResNeSt: Success
2021-08-18 23:22:25,141 [INFO]  <proc0> OpenData: Success
2021-08-18 23:23:49,858 [INFO]  <proc0> w9scan: Success
2021-08-18 23:27:11,035 [INFO]  <proc0> RAdam: Success
2021-08-18 23:27:50,609 [INFO]  <proc0> newscatcher: Success
2021-08-18 23:28:22,456 [ERROR]  Command 'None' in image 'sha256:c9272600db100822f045568c6986ac927dbd07ea4aa3c61f6dedbe2af3f13022' returned non-zero exit status 1: b'Traceback (most recent call last):\n  File "/GitHub520/fetch_ips.py", line 16, in <module>\n    from retry import retry\nModuleNotFoundError: No module named \'retry\'\n'
2021-08-18 23:28:22,456 [ERROR]  <proc0> GitHub520: RunFailed
2021-08-18 23:31:46,089 [INFO]  <proc0> vit-pytorch: Success
2021-08-18 23:32:07,226 [ERROR]  <proc0> Flask-HTTPAuth: BuildFailed
2021-08-18 23:32:37,948 [INFO]  <proc0> real-url: Success
2021-08-18 23:32:42,837 [ERROR]  <proc0> clearml: GenerateFailed
2021-08-18 23:33:06,552 [ERROR]  <proc0> captum: GenerateFailed
2021-08-18 23:33:22,794 [INFO]  <proc0> logzero: Success
2021-08-18 23:33:46,464 [INFO]  <proc0> arxiv-latex-cleaner: Success
2021-08-18 23:34:32,965 [INFO]  <proc0> GeneralNewsExtractor: Success
2021-08-18 23:35:06,538 [ERROR]  Command 'None' in image 'sha256:e7ce8794eb3760b81779c40ff3b13d64cf1636b5dc0300a9c51c73813fac23c5' returned non-zero exit status 1: b'Traceback (most recent call last):\n  File "/DXY-COVID-19-Crawler/main.py", line 12, in <module>\n    crawler.run()\n  File "/DXY-COVID-19-Crawler/service/crawler.py", line 31, in run\n    self.crawler()\n  File "/DXY-COVID-19-Crawler/service/crawler.py", line 46, in crawler\n    soup = BeautifulSoup(r.content, \'lxml\')\n  File "/usr/local/lib/python3.9/site-packages/bs4/__init__.py", line 243, in __init__\n    raise FeatureNotFound(\nbs4.FeatureNotFound: Couldn\'t find a tree builder with the features you requested: lxml. Do you need to install a parser library?\n'
2021-08-18 23:35:06,538 [ERROR]  <proc0> DXY-COVID-19-Crawler: Safe
2021-08-18 23:35:24,411 [ERROR]  Command 'None' in image 'sha256:ebd8de5077b1fdadf5e6a419d0faac198561c74f9fe7fcefc249d852337b3558' returned non-zero exit status 1: b'  File "pwnedornot.py", line 94\n    print(G + \'[+]\' + C + \' Checking Breach status for \' + W + \'{}\'.format(addr), end = \'\')\n                                                                                      ^\nSyntaxError: invalid syntax\n'
2021-08-18 23:35:24,411 [ERROR]  <proc0> pwnedOrNot: RunFailed
2021-08-18 23:36:34,187 [INFO]  <proc0> gplearn: Success
2021-08-18 23:37:28,203 [INFO]  <proc0> m2cgen: Success
2021-08-18 23:39:40,937 [INFO]  <proc0> dirmap: Success
2021-08-18 23:39:54,362 [INFO]  <proc0> latexify_py: Success
2021-08-18 23:40:50,854 [ERROR]  Command 'None' in image 'sha256:c4e0842bfeef6c9cebf2270c30b6dbfe274e2573dee2588b47ecb80aa614fc7a' returned non-zero exit status 1: b'Traceback (most recent call last):\n  File "/springer_free_books/main.py", line 48, in <module>\n    books = pd.read_excel(table_url)\n  File "/usr/local/lib/python3.9/site-packages/pandas/util/_decorators.py", line 299, in wrapper\n    return func(*args, **kwargs)\n  File "/usr/local/lib/python3.9/site-packages/pandas/io/excel/_base.py", line 336, in read_excel\n    io = ExcelFile(io, storage_options=storage_options, engine=engine)\n  File "/usr/local/lib/python3.9/site-packages/pandas/io/excel/_base.py", line 1131, in __init__\n    self._reader = self._engines[engine](self._io, storage_options=storage_options)\n  File "/usr/local/lib/python3.9/site-packages/pandas/io/excel/_xlrd.py", line 24, in __init__\n    import_optional_dependency("xlrd", extra=err_msg)\n  File "/usr/local/lib/python3.9/site-packages/pandas/compat/_optional.py", line 109, in import_optional_dependency\n    raise ImportError(msg) from None\nImportError: Missing optional dependency \'xlrd\'. Install xlrd >= 1.0.0 for Excel support Use pip or conda to install xlrd.\n'
2021-08-18 23:40:50,854 [ERROR]  <proc0> springer_free_books: RunFailed
2021-08-18 23:41:25,575 [INFO]  <proc0> bilibili-api: Success
2021-08-18 23:41:25,996 [ERROR]  <proc0> babel: GenerateFailed
2021-08-18 23:41:37,300 [INFO]  <proc0> coding-problems: Success
2021-08-18 23:41:54,914 [INFO]  <proc0> dongbei: Success
2021-08-18 23:42:46,835 [INFO]  <proc0> returns: Success
2021-08-18 23:43:05,714 [INFO]  <proc0> xxh: Success
2021-08-18 23:46:33,442 [INFO]  <proc0> blind_watermark: Success
2021-08-18 23:49:53,762 [INFO]  <proc0> pandarallel: Success
2021-08-18 23:52:12,771 [INFO]  <proc0> DecryptLogin: Inconsistent
2021-08-18 23:52:13,184 [ERROR]  <proc0> webpy: GenerateFailed
2021-08-18 23:53:12,649 [INFO]  <proc0> SSRFmap: Success
2021-08-18 23:53:31,763 [INFO]  <proc0> doublepulsar-detection-script: Success
2021-08-18 23:58:54,789 [INFO]  <proc0> lambda-networks: Success
2021-08-18 23:58:55,945 [ERROR]  <proc0> weakfilescan: GenerateFailed
2021-08-19 00:04:22,806 [INFO]  <proc0> pytorch-openai-transformer-lm: Success
2021-08-19 00:04:25,468 [ERROR]  <proc0> pwncat: GenerateFailed
2021-08-19 00:06:12,482 [INFO]  <proc0> uncertainty-toolbox: Success
2021-08-19 00:06:13,511 [ERROR]  <proc0> SSRSpeed: GenerateFailed
2021-08-19 00:06:15,939 [ERROR]  <proc0> dirsearch: GenerateFailed
2021-08-19 00:07:40,560 [INFO]  <proc0> commitment: Success
2021-08-19 00:09:11,000 [INFO]  <proc0> 30-Days-Of-Python: Success
2021-08-19 00:14:14,938 [INFO]  <proc0> Vxscan: Inconsistent
2021-08-19 00:15:18,015 [INFO]  <proc0> galaxy-integrations-python-api: Success
2021-08-19 00:15:59,983 [INFO]  <proc0> mitm6: Success
2021-08-19 00:18:16,969 [ERROR]  <proc0> flask-celery-example: BuildFailed
2021-08-19 00:24:43,112 [INFO]  <proc0> proxylessnas: Success
2021-08-19 00:27:33,879 [INFO]  <proc0> sweetviz: Success
2021-08-19 00:28:13,629 [INFO]  <proc0> policy_sentry: Success
2021-08-19 00:29:49,623 [INFO]  <proc0> noisy: Success
2021-08-19 00:38:45,929 [INFO]  <proc0> pytorch-meta: Success
2021-08-19 00:38:57,844 [INFO]  <proc0> path: Success
2021-08-19 00:39:12,052 [INFO]  <proc0> WeblogicScan: Success
2021-08-19 00:40:42,911 [INFO]  <proc0> heartrate: Inconsistent
2021-08-19 00:41:51,839 [ERROR]  <proc0> plotman: BuildFailed
2021-08-19 00:44:08,230 [INFO]  <proc0> karateclub: Inconsistent
2021-08-19 00:45:48,463 [INFO]  <proc0> archivy: Inconsistent
2021-08-19 00:49:19,674 [ERROR]  Command 'None' in image 'sha256:6a3ee209cb1a2a508a6a4b114fe87341244519990c48546c3d912ae71732133e' returned non-zero exit status 1: b'2021-08-18 16:49:15.367365: W tensorflow/stream_executor/platform/default/dso_loader.cc:60] Could not load dynamic library \'libcudart.so.11.0\'; dlerror: libcudart.so.11.0: cannot open shared object file: No such file or directory\n2021-08-18 16:49:15.367394: I tensorflow/stream_executor/cuda/cudart_stub.cc:29] Ignore above cudart dlerror if you do not have a GPU set up on your machine.\nTraceback (most recent call last):\n  File "train.py", line 8, in <module>\n    from gcn.models import GCN, MLP\n  File "/gcn/gcn/models.py", line 1, in <module>\n    from gcn.layers import *\n  File "/gcn/gcn/layers.py", line 4, in <module>\n    flags = tf.app.flags\nAttributeError: module \'tensorflow\' has no attribute \'app\'\n'
2021-08-19 00:49:19,674 [ERROR]  <proc0> gcn: Safe
2021-08-19 00:49:20,211 [ERROR]  <proc0> sentry-python: GenerateFailed
2021-08-19 00:51:02,045 [INFO]  <proc0> django-vue-template: Success
2021-08-19 00:52:27,080 [INFO]  <proc0> GScan: Success
2021-08-19 00:52:27,193 [ERROR]  <proc0> kaldi-gstreamer-server: GenerateFailed
2021-08-19 01:00:26,492 [INFO]  <proc0> flops-counter.pytorch: Success
2021-08-19 01:01:12,950 [ERROR]  Command 'None' in image 'sha256:7205865e32e44dc5ec2f30572acf8e22a6957edea090269becc1029cea8e7d03' returned non-zero exit status 1: b'Traceback (most recent call last):\n  File "/usr/local/bin/profil3r", line 5, in <module>\n    from profil3r.main import main\n  File "/usr/local/lib/python3.9/site-packages/profil3r/main.py", line 1, in <module>\n    from profil3r.app import Core\n  File "/usr/local/lib/python3.9/site-packages/profil3r/app/__init__.py", line 59, in <module>\n    exec("""\n  File "<string>", line 2, in <module>\n  File "/usr/local/lib/python3.9/site-packages/profil3r/app/modules/email/email.py", line 2, in <module>\n    import pwnedpasswords\nModuleNotFoundError: No module named \'pwnedpasswords\'\n'
2021-08-19 01:01:12,950 [ERROR]  <proc0> Profil3r: RunFailed
2021-08-19 01:02:13,001 [INFO]  <proc0> nba_api: Success
2021-08-19 01:05:50,613 [INFO]  <proc0> micronet: Success
2021-08-19 01:32:17,947 [INFO]  <proc0> pke: Inconsistent
2021-08-19 01:32:59,358 [INFO]  <proc0> BlueKeep: Success
2021-08-19 01:33:34,340 [INFO]  <proc0> pygooglenews: Success
2021-08-19 01:46:51,622 [INFO]  <proc0> petastorm: Success
2021-08-19 01:50:00,326 [ERROR]  Command 'None' in image 'sha256:056b31c6c4c218ab490fe80c3ca8d278b936c35229a3293b17ecf937994962ca' returned non-zero exit status 1: b'Traceback (most recent call last):\n  File "/blackhat-python3/chapter04/pic_carver.py", line 2, in <module>\n    from kamene.all import *\nModuleNotFoundError: No module named \'kamene\'\n'
2021-08-19 01:50:00,326 [ERROR]  <proc0> blackhat-python3: RunFailed
2021-08-19 01:56:08,484 [ERROR]  Command 'None' in image 'sha256:fa543e056fe890964f669c37972fbc5e124d0d05198912aae519bb895302541d' returned non-zero exit status 1: b'Traceback (most recent call last):\n  File "/neural_prophet/test.py", line 1, in <module>\n    from neuralprophet import NeuralProphet\n  File "/neural_prophet/neuralprophet/__init__.py", line 24, in <module>\n    from .forecaster import NeuralProphet\n  File "/neural_prophet/neuralprophet/forecaster.py", line 11, in <module>\n    from torch_lr_finder import LRFinder\nModuleNotFoundError: No module named \'torch_lr_finder\'\n'
2021-08-19 01:56:08,484 [ERROR]  <proc0> neural_prophet: RunFailed
2021-08-19 01:56:30,999 [INFO]  <proc0> pyp: Success
2021-08-19 02:02:18,478 [INFO]  <proc0> SimpleHTR: Success
2021-08-19 02:08:59,640 [INFO]  <proc0> SuperGluePretrainedNetwork: Success
2021-08-19 02:15:06,477 [INFO]  <proc0> SuperPointPretrainedNetwork: Success
2021-08-19 02:16:02,423 [ERROR]  Command 'None' in image 'sha256:69d7e54b9bd7e91f3d5ec4f938802896232c200d1eb717cafbf1082c810c2e23' returned non-zero exit status 1: b'Traceback (most recent call last):\n  File "/Packer-Fuzzer/PackerFuzzer.py", line 4, in <module>\n    from lib.Controller import Project\n  File "/Packer-Fuzzer/lib/Controller.py", line 15, in <module>\n    from lib.Recoverspilt import RecoverSpilt\n  File "/Packer-Fuzzer/lib/Recoverspilt.py", line 4, in <module>\n    import node_vm2, os, re, sqlite3\nModuleNotFoundError: No module named \'node_vm2\'\n'
2021-08-19 02:16:02,424 [ERROR]  <proc0> Packer-Fuzzer: RunFailed
2021-08-19 02:19:41,067 [ERROR]  Command 'None' in image 'sha256:a1c4b27977f0515a5c76e1df0b444348dd579b214423c00f1f0cac1e1805caf2' returned non-zero exit status 1: b'2021-08-18 18:19:38.411498: W tensorflow/stream_executor/platform/default/dso_loader.cc:59] Could not load dynamic library \'libcudart.so.10.1\'; dlerror: libcudart.so.10.1: cannot open shared object file: No such file or directory\n2021-08-18 18:19:38.411540: I tensorflow/stream_executor/cuda/cudart_stub.cc:29] Ignore above cudart dlerror if you do not have a GPU set up on your machine.\nTraceback (most recent call last):\n  File "test.py", line 5, in <module>\n    from keras.applications.imagenet_utils import decode_predictions\n  File "/usr/local/lib/python3.8/site-packages/keras/__init__.py", line 25, in <module>\n    from keras import models\n  File "/usr/local/lib/python3.8/site-packages/keras/models.py", line 19, in <module>\n    from keras import backend\n  File "/usr/local/lib/python3.8/site-packages/keras/backend.py", line 36, in <module>\n    from tensorflow.python.eager.context import get_config\nImportError: cannot import name \'get_config\' from \'tensorflow.python.eager.context\' (/usr/local/lib/python3.8/site-packages/tensorflow/python/eager/context.py)\n'
2021-08-19 02:19:41,068 [ERROR]  <proc0> efficientnet: RunFailed
2021-08-19 02:25:16,224 [ERROR]  Command 'None' in image 'sha256:83150dab9930f2f60335862e3d2bbd4eaa3d6c4633ef3118534e470e3063d629' returned non-zero exit status 1: b'2021-08-18 18:25:13.189670: W tensorflow/stream_executor/platform/default/dso_loader.cc:60] Could not load dynamic library \'libcudart.so.11.0\'; dlerror: libcudart.so.11.0: cannot open shared object file: No such file or directory\n2021-08-18 18:25:13.189701: I tensorflow/stream_executor/cuda/cudart_stub.cc:29] Ignore above cudart dlerror if you do not have a GPU set up on your machine.\nTraceback (most recent call last):\n  File "image_demo.py", line 33, in <module>\n    return_tensors = utils.read_pb_return_tensors(graph, pb_file, return_elements)\n  File "/tensorflow-yolov3/core/utils.py", line 122, in read_pb_return_tensors\n    with tf.gfile.FastGFile(pb_file, \'rb\') as f:\nAttributeError: module \'tensorflow\' has no attribute \'gfile\'\n'
2021-08-19 02:25:16,225 [ERROR]  <proc0> tensorflow-yolov3: Safe
2021-08-19 02:25:35,633 [INFO]  <proc0> doge: Success
2021-08-19 02:25:43,063 [ERROR]  <proc0> mars: GenerateFailed
2021-08-19 02:26:12,020 [INFO]  <proc0> peru: Success
2021-08-19 02:26:40,443 [INFO]  <proc0> starlette: Inconsistent
2021-08-19 02:26:40,443 [INFO]  62/100, 0.62
2021-08-19 02:26:40,443 [INFO]  ----------END----------
