Namespace(actions='*', architecture='3,3,3,3,3', batch_size=1024, bone_length_term=True, by_subject=False, causal=False, channels=1024, checkpoint='checkpoint', checkpoint_frequency=10, data_augmentation=True, dataset='h36m', dense=False, disable_optimizations=False, downsample=1, dropout=0.25, epochs=60, evaluate='pretrained_h36m_cpn.bin', export_training_curves=False, keypoints='cpn_ft_h36m_dbb', learning_rate=0.001, linear_projection=False, lr_decay=0.95, no_eval=False, no_proj=False, render=False, resume='', stride=1, subjects_test='S9,S11', subjects_train='S1,S5,S6,S7,S8', subjects_unlabeled='', subset=1, test_time_augmentation=True, viz_action=None, viz_bitrate=3000, viz_camera=0, viz_downsample=1, viz_export=None, viz_limit=-1, viz_no_ground_truth=False, viz_output=None, viz_size=5, viz_skip=0, viz_subject=None, viz_video=None, warmup=1)
Loading dataset...
Traceback (most recent call last):
  File "run.py", line 41, in <module>
    dataset = Human36mDataset(dataset_path)
  File "/VideoPose3D/common/h36m_dataset.py", line 234, in __init__
    data = np.load(path, allow_pickle=True)['positions_3d'].item()
  File "/usr/local/lib/python3.8/site-packages/numpy/lib/npyio.py", line 417, in load
    fid = stack.enter_context(open(os_fspath(file), "rb"))
FileNotFoundError: [Errno 2] No such file or directory: 'data/data_3d_h36m.npz'
